Workbook

Sheet Base vs Growth vs Downside key
A1: Base vs Growth vs Downside: key metrics
A2: Summary · Downside
A4: Variable / dimension | B4: 2026-11 | C4: 2026-12 | D4: 2027-01 | E4: 2027-02 | F4: 2027-03 | G4: 2027-04 | H4: 2027-05 | I4: 2027-06 | J4: 2027-07 | K4: 2027-08 | L4: 2027-09 | M4: 2027-10 | N4: 2027-11 | O4: 2027-12 | P4: 2028-01 | Q4: 2028-02 | R4: 2028-03 | S4: 2028-04 | T4: 2028-05 | U4: 2028-06 | V4: 2028-07 | W4: 2028-08 | X4: 2028-09 | Y4: 2028-10
A5: Customers | B5: =SUM('Model inputs'!B7,'Model inputs'!B8) -> 0 | C5: =SUM('Model inputs'!C7,'Model inputs'!C8) -> 0 | D5: =SUM('Model inputs'!D7,'Model inputs'!D8) -> 0 | E5: =SUM('Model inputs'!E7,'Model inputs'!E8) -> 0 | F5: =SUM('Model inputs'!F7,'Model inputs'!F8) -> 0 | G5: =SUM('Model inputs'!G7,'Model inputs'!G8) -> 0 | H5: =SUM('Model inputs'!H7,'Model inputs'!H8) -> 2 | I5: =SUM('Model inputs'!I7,'Model inputs'!I8) -> 4 | ... Y5: =SUM('Model inputs'!Y7,'Model inputs'!Y8) -> 42
A6: Customers > Growth | B6: =SUM('Model inputs'!B10,'Model inputs'!B11) -> 0 | C6: =SUM('Model inputs'!C10,'Model inputs'!C11) -> 0 | D6: =SUM('Model inputs'!D10,'Model inputs'!D11) -> 0 | E6: =SUM('Model inputs'!E10,'Model inputs'!E11) -> 4 | F6: =SUM('Model inputs'!F10,'Model inputs'!F11) -> 8 | G6: =SUM('Model inputs'!G10,'Model inputs'!G11) -> 12 | H6: =SUM('Model inputs'!H10,'Model inputs'!H11) -> 17 | I6: =SUM('Model inputs'!I10,'Model inputs'!I11) -> 22 | ... Y6: =SUM('Model inputs'!Y10,'Model inputs'!Y11) -> 125
A7: Customers > delta | B7: ='Base vs Growth vs Downside key'!B6-'Base vs Growth vs Downside key'!B5 -> 0 | C7: ='Base vs Growth vs Downside key'!C6-'Base vs Growth vs Downside key'!C5 -> 0 | D7: ='Base vs Growth vs Downside key'!D6-'Base vs Growth vs Downside key'!D5 -> 0 | E7: ='Base vs Growth vs Downside key'!E6-'Base vs Growth vs Downside key'!E5 -> 4 | F7: ='Base vs Growth vs Downside key'!F6-'Base vs Growth vs Downside key'!F5 -> 8 | G7: ='Base vs Growth vs Downside key'!G6-'Base vs Growth vs Downside key'!G5 -> 12 | H7: ='Base vs Growth vs Downside key'!H6-'Base vs Growth vs Downside key'!H5 -> 15 | I7: ='Base vs Growth vs Downside key'!I6-'Base vs Growth vs Downside key'!I5 -> 18 | ... Y7: ='Base vs Growth vs Downside key'!Y6-'Base vs Growth vs Downside key'!Y5 -> 83
A8: Revenue | B8: =SUM('Model inputs'!B21,'Model inputs'!B22) -> 0 | C8: =SUM('Model inputs'!C21,'Model inputs'!C22) -> 0 | D8: =SUM('Model inputs'!D21,'Model inputs'!D22) -> 0 | E8: =SUM('Model inputs'!E21,'Model inputs'!E22) -> 0 | F8: =SUM('Model inputs'!F21,'Model inputs'!F22) -> 0 | G8: =SUM('Model inputs'!G21,'Model inputs'!G22) -> 0 | H8: =SUM('Model inputs'!H21,'Model inputs'!H22) -> 198 | I8: =SUM('Model inputs'!I21,'Model inputs'!I22) -> 696 | ... Y8: =SUM('Model inputs'!Y21,'Model inputs'!Y22) -> 6558
A9: Revenue > Growth | B9: =SUM('Model inputs'!B24,'Model inputs'!B25) -> 0 | C9: =SUM('Model inputs'!C24,'Model inputs'!C25) -> 0 | D9: =SUM('Model inputs'!D24,'Model inputs'!D25) -> 0 | E9: =SUM('Model inputs'!E24,'Model inputs'!E25) -> 696 | F9: =SUM('Model inputs'!F24,'Model inputs'!F25) -> 1092 | G9: =SUM('Model inputs'!G24,'Model inputs'!G25) -> 1788 | H9: =SUM('Model inputs'!H24,'Model inputs'!H25) -> 2583 | I9: =SUM('Model inputs'!I24,'Model inputs'!I25) -> 3378 | ... Y9: =SUM('Model inputs'!Y24,'Model inputs'!Y25) -> 19875
A10: Revenue > delta | B10: ='Base vs Growth vs Downside key'!B9-'Base vs Growth vs Downside key'!B8 -> 0 | C10: ='Base vs Growth vs Downside key'!C9-'Base vs Growth vs Downside key'!C8 -> 0 | D10: ='Base vs Growth vs Downside key'!D9-'Base vs Growth vs Downside key'!D8 -> 0 | E10: ='Base vs Growth vs Downside key'!E9-'Base vs Growth vs Downside key'!E8 -> 696 | F10: ='Base vs Growth vs Downside key'!F9-'Base vs Growth vs Downside key'!F8 -> 1092 | G10: ='Base vs Growth vs Downside key'!G9-'Base vs Growth vs Downside key'!G8 -> 1788 | H10: ='Base vs Growth vs Downside key'!H9-'Base vs Growth vs Downside key'!H8 -> 2385 | I10: ='Base vs Growth vs Downside key'!I9-'Base vs Growth vs Downside key'!I8 -> 2682 | ... Y10: ='Base vs Growth vs Downside key'!Y9-'Base vs Growth vs Downside key'!Y8 -> 13317
A11: Gross margin | B11: =IFERROR('Model inputs'!B14/'Base vs Growth vs Downside key'!B8,"") | C11: =IFERROR('Model inputs'!C14/'Base vs Growth vs Downside key'!C8,"") | D11: =IFERROR('Model inputs'!D14/'Base vs Growth vs Downside key'!D8,"") | E11: =IFERROR('Model inputs'!E14/'Base vs Growth vs Downside key'!E8,"") | F11: =IFERROR('Model inputs'!F14/'Base vs Growth vs Downside key'!F8,"") | G11: =IFERROR('Model inputs'!G14/'Base vs Growth vs Downside key'!G8,"") | H11: =IFERROR('Model inputs'!H14/'Base vs Growth vs Downside key'!H8,"") -> 0.29454545 | I11: =IFERROR('Model inputs'!I14/'Base vs Growth vs Downside key'!I8,"") -> 0.26275862 | ... Y11: =IFERROR('Model inputs'!Y14/'Base vs Growth vs Downside key'!Y8,"") -> 0.29537054
A12: Gross margin > Growth | B12: =IFERROR('Model inputs'!B15/'Base vs Growth vs Downside key'!B9,"") | C12: =IFERROR('Model inputs'!C15/'Base vs Growth vs Downside key'!C9,"") | D12: =IFERROR('Model inputs'!D15/'Base vs Growth vs Downside key'!D9,"") | E12: =IFERROR('Model inputs'!E15/'Base vs Growth vs Downside key'!E9,"") -> 0.68864368 | F12: =IFERROR('Model inputs'!F15/'Base vs Growth vs Downside key'!F9,"") -> 0.70928938 | G12: =IFERROR('Model inputs'!G15/'Base vs Growth vs Downside key'!G9,"") -> 0.70975391 | H12: =IFERROR('Model inputs'!H15/'Base vs Growth vs Downside key'!H9,"") -> 0.71132327 | I12: =IFERROR('Model inputs'!I15/'Base vs Growth vs Downside key'!I9,"") -> 0.71215394 | ... Y12: =IFERROR('Model inputs'!Y15/'Base vs Growth vs Downside key'!Y9,"") -> 0.71408805
A13: Gross margin > delta | H13: ='Base vs Growth vs Downside key'!H12-'Base vs Growth vs Downside key'!H11 -> 0.41677781 | I13: ='Base vs Growth vs Downside key'!I12-'Base vs Growth vs Downside key'!I11 -> 0.44939532 | J13: ='Base vs Growth vs Downside key'!J12-'Base vs Growth vs Downside key'!J11 -> 0.42662982 | K13: ='Base vs Growth vs Downside key'!K12-'Base vs Growth vs Downside key'!K11 -> 0.4115293 | L13: ='Base vs Growth vs Downside key'!L12-'Base vs Growth vs Downside key'!L11 -> 0.42797997 | M13: ='Base vs Growth vs Downside key'!M12-'Base vs Growth vs Downside key'!M11 -> 0.4186382 | N13: ='Base vs Growth vs Downside key'!N12-'Base vs Growth vs Downside key'!N11 -> 0.4115709 | O13: ='Base vs Growth vs Downside key'!O12-'Base vs Growth vs Downside key'!O11 -> 0.42153065 | ... Y13: ='Base vs Growth vs Downside key'!Y12-'Base vs Growth vs Downside key'!Y11 -> 0.41871751
A14: Net burn | B14: =-'Model inputs'!B18 -> 2115.2 | C14: =-'Model inputs'!C18 -> 2115.2 | D14: =-'Model inputs'!D18 -> 2115.2 | E14: =-'Model inputs'!E18 -> 2115.2 | F14: =-'Model inputs'!F18 -> 2115.2 | G14: =-'Model inputs'!G18 -> 2115.2 | H14: =-'Model inputs'!H18 -> 2041.68 | I14: =-'Model inputs'!I18 -> 1917.12 | ... Y14: =-'Model inputs'!Y18 -> 162.96
A15: Net burn > Growth | B15: =-'Model inputs'!B19 -> 2115.2 | C15: =-'Model inputs'!C19 -> 2115.2 | D15: =-'Model inputs'!D19 -> 2115.2 | E15: =-'Model inputs'!E19 -> 1620.704 | F15: =-'Model inputs'!F19 -> 1325.456 | G15: =-'Model inputs'!G19 -> 830.96 | H15: =-'Model inputs'!H19 -> 262.652 | I15: =-'Model inputs'!I19 -> -305.656 | ... Y15: =-'Model inputs'!Y19 -> -12092.5
A16: Net burn > delta | B16: ='Base vs Growth vs Downside key'!B15-'Base vs Growth vs Downside key'!B14 -> 0 | C16: ='Base vs Growth vs Downside key'!C15-'Base vs Growth vs Downside key'!C14 -> 0 | D16: ='Base vs Growth vs Downside key'!D15-'Base vs Growth vs Downside key'!D14 -> 0 | E16: ='Base vs Growth vs Downside key'!E15-'Base vs Growth vs Downside key'!E14 -> -494.496 | F16: ='Base vs Growth vs Downside key'!F15-'Base vs Growth vs Downside key'!F14 -> -789.744 | G16: ='Base vs Growth vs Downside key'!G15-'Base vs Growth vs Downside key'!G14 -> -1284.24 | H16: ='Base vs Growth vs Downside key'!H15-'Base vs Growth vs Downside key'!H14 -> -1779.028 | I16: ='Base vs Growth vs Downside key'!I15-'Base vs Growth vs Downside key'!I14 -> -2222.776 | ... Y16: ='Base vs Growth vs Downside key'!Y15-'Base vs Growth vs Downside key'!Y14 -> -12255.46
A17: Ending cash | B17: =IF(IF(IF(IF(ISERROR('Model inputs'!B16=1),'Model inputs'!B16=1,IF('Model inputs'!B16="","",'Model inputs'!B16=1))="",FALSE,IF(ISERROR('Model inputs'!B16=1),'Model inputs'!B16=1,IF('Model inputs'!B16="","",'Model inputs'!B16=1))),IF('Model inputs'!AB26="","",'Model inputs'!AB26),IF('Model inputs'!AA12="","",'Model inputs'!AA12))="",0,IF(IF(IF(ISERROR('Model inputs'!B16=1),'Model inputs'!B16=1,IF('Model inputs'!B16="","",'Model inputs'!B16=1))="",FALSE,IF(ISERROR('Model inputs'!B16=1),'Model inputs'!B16=1,IF('Model inputs'!B16="","",'Model inputs'!B16=1))),IF('Model inputs'!AB26="","",'Model inputs'!AB26),IF('Model inputs'!AA12="","",'Model inputs'!AA12)))+'Model inputs'!B18 -> 22884.8 | C17: =IF(IF(IF(IF(ISERROR('Model inputs'!C16=1),'Model inputs'!C16=1,IF('Model inputs'!C16="","",'Model inputs'!C16=1))="",FALSE,IF(ISERROR('Model inputs'!C16=1),'Model inputs'!C16=1,IF('Model inputs'!C16="","",'Model inputs'!C16=1))),IF('Model inputs'!AB26="","",'Model inputs'!AB26),IF('Base vs Growth vs Downside key'!B17="","",'Base vs Growth vs Downside key'!B17))="",0,IF(IF(IF(ISERROR('Model inputs'!C16=1),'Model inputs'!C16=1,IF('Model inputs'!C16="","",'Model inputs'!C16=1))="",FALSE,IF(ISERROR('Model inputs'!C16=1),'Model inputs'!C16=1,IF('Model inputs'!C16="","",'Model inputs'!C16=1))),IF('Model inputs'!AB26="","",'Model inputs'!AB26),IF('Base vs Growth vs Downside key'!B17="","",'Base vs Growth vs Downside key'!B17)))+'Model inputs'!C18 -> 20769.6 | D17: =IF(IF(IF(IF(ISERROR('Model inputs'!D16=1),'Model inputs'!D16=1,IF('Model inputs'!D16="","",'Model inputs'!D16=1))="",FALSE,IF(ISERROR('Model inputs'!D16=1),'Model inputs'!D16=1,IF('Model inputs'!D16="","",'Model inputs'!D16=1))),IF('Model inputs'!AB26="","",'Model inputs'!AB26),IF('Base vs Growth vs Downside key'!C17="","",'Base vs Growth vs Downside key'!C17))="",0,IF(IF(IF(ISERROR('Model inputs'!D16=1),'Model inputs'!D16=1,IF('Model inputs'!D16="","",'Model inputs'!D16=1))="",FALSE,IF(ISERROR('Model inputs'!D16=1),'Model inputs'!D16=1,IF('Model inputs'!D16="","",'Model inputs'!D16=1))),IF('Model inputs'!AB26="","",'Model inputs'!AB26),IF('Base vs Growth vs Downside key'!C17="","",'Base vs Growth vs Downside key'!C17)))+'Model inputs'!D18 -> 18654.4 | E17: =IF(IF(IF(IF(ISERROR('Model inputs'!E16=1),'Model inputs'!E16=1,IF('Model inputs'!E16="","",'Model inputs'!E16=1))="",FALSE,IF(ISERROR('Model inputs'!E16=1),'Model inputs'!E16=1,IF('Model inputs'!E16="","",'Model inputs'!E16=1))),IF('Model inputs'!AB26="","",'Model inputs'!AB26),IF('Base vs Growth vs Downside key'!D17="","",'Base vs Growth vs Downside key'!D17))="",0,IF(IF(IF(ISERROR('Model inputs'!E16=1),'Model inputs'!E16=1,IF('Model inputs'!E16="","",'Model inputs'!E16=1))="",FALSE,IF(ISERROR('Model inputs'!E16=1),'Model inputs'!E16=1,IF('Model inputs'!E16="","",'Model inputs'!E16=1))),IF('Model inputs'!AB26="","",'Model inputs'!AB26),IF('Base vs Growth vs Downside key'!D17="","",'Base vs Growth vs Downside key'!D17)))+'Model inputs'!E18 -> 16539.2 | F17: =IF(IF(IF(IF(ISERROR('Model inputs'!F16=1),'Model inputs'!F16=1,IF('Model inputs'!F16="","",'Model inputs'!F16=1))="",FALSE,IF(ISERROR('Model inputs'!F16=1),'Model inputs'!F16=1,IF('Model inputs'!F16="","",'Model inputs'!F16=1))),IF('Model inputs'!AB26="","",'Model inputs'!AB26),IF('Base vs Growth vs Downside key'!E17="","",'Base vs Growth vs Downside key'!E17))="",0,IF(IF(IF(ISERROR('Model inputs'!F16=1),'Model inputs'!F16=1,IF('Model inputs'!F16="","",'Model inputs'!F16=1))="",FALSE,IF(ISERROR('Model inputs'!F16=1),'Model inputs'!F16=1,IF('Model inputs'!F16="","",'Model inputs'!F16=1))),IF('Model inputs'!AB26="","",'Model inputs'!AB26),IF('Base vs Growth vs Downside key'!E17="","",'Base vs Growth vs Downside key'!E17)))+'Model inputs'!F18 -> 14424 | G17: =IF(IF(IF(IF(ISERROR('Model inputs'!G16=1),'Model inputs'!G16=1,IF('Model inputs'!G16="","",'Model inputs'!G16=1))="",FALSE,IF(ISERROR('Model inputs'!G16=1),'Model inputs'!G16=1,IF('Model inputs'!G16="","",'Model inputs'!G16=1))),IF('Model inputs'!AB26="","",'Model inputs'!AB26),IF('Base vs Growth vs Downside key'!F17="","",'Base vs Growth vs Downside key'!F17))="",0,IF(IF(IF(ISERROR('Model inputs'!G16=1),'Model inputs'!G16=1,IF('Model inputs'!G16="","",'Model inputs'!G16=1))="",FALSE,IF(ISERROR('Model inputs'!G16=1),'Model inputs'!G16=1,IF('Model inputs'!G16="","",'Model inputs'!G16=1))),IF('Model inputs'!AB26="","",'Model inputs'!AB26),IF('Base vs Growth vs Downside key'!F17="","",'Base vs Growth vs Downside key'!F17)))+'Model inputs'!G18 -> 12308.8 | H17: =IF(IF(IF(IF(ISERROR('Model inputs'!H16=1),'Model inputs'!H16=1,IF('Model inputs'!H16="","",'Model inputs'!H16=1))="",FALSE,IF(ISERROR('Model inputs'!H16=1),'Model inputs'!H16=1,IF('Model inputs'!H16="","",'Model inputs'!H16=1))),IF('Model inputs'!AB26="","",'Model inputs'!AB26),IF('Base vs Growth vs Downside key'!G17="","",'Base vs Growth vs Downside key'!G17))="",0,IF(IF(IF(ISERROR('Model inputs'!H16=1),'Model inputs'!H16=1,IF('Model inputs'!H16="","",'Model inputs'!H16=1))="",FALSE,IF(ISERROR('Model inputs'!H16=1),'Model inputs'!H16=1,IF('Model inputs'!H16="","",'Model inputs'!H16=1))),IF('Model inputs'!AB26="","",'Model inputs'!AB26),IF('Base vs Growth vs Downside key'!G17="","",'Base vs Growth vs Downside key'!G17)))+'Model inputs'!H18 -> 10267.12 | I17: =IF(IF(IF(IF(ISERROR('Model inputs'!I16=1),'Model inputs'!I16=1,IF('Model inputs'!I16="","",'Model inputs'!I16=1))="",FALSE,IF(ISERROR('Model inputs'!I16=1),'Model inputs'!I16=1,IF('Model inputs'!I16="","",'Model inputs'!I16=1))),IF('Model inputs'!AB26="","",'Model inputs'!AB26),IF('Base vs Growth vs Downside key'!H17="","",'Base vs Growth vs Downside key'!H17))="",0,IF(IF(IF(ISERROR('Model inputs'!I16=1),'Model inputs'!I16=1,IF('Model inputs'!I16="","",'Model inputs'!I16=1))="",FALSE,IF(ISERROR('Model inputs'!I16=1),'Model inputs'!I16=1,IF('Model inputs'!I16="","",'Model inputs'!I16=1))),IF('Model inputs'!AB26="","",'Model inputs'!AB26),IF('Base vs Growth vs Downside key'!H17="","",'Base vs Growth vs Downside key'!H17)))+'Model inputs'!I18 -> 8350 | J17: =IF(IF(IF(IF(ISERROR('Model inputs'!J16=1),'Model inputs'!J16=1,IF('Model inputs'!J16="","",'Model inputs'!J16=1))="",FALSE,IF(ISERROR('Model inputs'!J16=1),'Model inputs'!J16=1,IF('Model inputs'!J16="","",'Model inputs'!J16=1))),IF('Model inputs'!AB26="","",'Model inputs'!AB26),IF('Base vs Growth vs Downside key'!I17="","",'Base vs Growth vs Downside key'!I17))="",0,IF(IF(IF(ISERROR('Model inputs'!J16=1),'Model inputs'!J16=1,IF('Model inputs'!J16="","",'Model inputs'!J16=1))="",FALSE,IF(ISERROR('Model inputs'!J16=1),'Model inputs'!J16=1,IF('Model inputs'!J16="","",'Model inputs'!J16=1))),IF('Model inputs'!AB26="","",'Model inputs'!AB26),IF('Base vs Growth vs Downside key'!I17="","",'Base vs Growth vs Downside key'!I17)))+'Model inputs'!J18 -> 6506.4 | K17: =IF(IF(IF(IF(ISERROR('Model inputs'!K16=1),'Model inputs'!K16=1,IF('Model inputs'!K16="","",'Model inputs'!K16=1))="",FALSE,IF(ISERROR('Model inputs'!K16=1),'Model inputs'!K16=1,IF('Model inputs'!K16="","",'Model inputs'!K16=1))),IF('Model inputs'!AB26="","",'Model inputs'!AB26),IF('Base vs Growth vs Downside key'!J17="","",'Base vs Growth vs Downside key'!J17))="",0,IF(IF(IF(ISERROR('Model inputs'!K16=1),'Model inputs'!K16=1,IF('Model inputs'!K16="","",'Model inputs'!K16=1))="",FALSE,IF(ISERROR('Model inputs'!K16=1),'Model inputs'!K16=1,IF('Model inputs'!K16="","",'Model inputs'!K16=1))),IF('Model inputs'!AB26="","",'Model inputs'!AB26),IF('Base vs Growth vs Downside key'!J17="","",'Base vs Growth vs Downside key'!J17)))+'Model inputs'!K18 -> 4736.32 | L17: =IF(IF(IF(IF(ISERROR('Model inputs'!L16=1),'Model inputs'!L16=1,IF('Model inputs'!L16="","",'Model inputs'!L16=1))="",FALSE,IF(ISERROR('Model inputs'!L16=1),'Model inputs'!L16=1,IF('Model inputs'!L16="","",'Model inputs'!L16=1))),IF('Model inputs'!AB26="","",'Model inputs'!AB26),IF('Base vs Growth vs Downside key'!K17="","",'Base vs Growth vs Downside key'!K17))="",0,IF(IF(IF(ISERROR('Model inputs'!L16=1),'Model inputs'!L16=1,IF('Model inputs'!L16="","",'Model inputs'!L16=1))="",FALSE,IF(ISERROR('Model inputs'!L16=1),'Model inputs'!L16=1,IF('Model inputs'!L16="","",'Model inputs'!L16=1))),IF('Model inputs'!AB26="","",'Model inputs'!AB26),IF('Base vs Growth vs Downside key'!K17="","",'Base vs Growth vs Downside key'!K17)))+'Model inputs'!L18 -> 3090.8 | M17: =IF(IF(IF(IF(ISERROR('Model inputs'!M16=1),'Model inputs'!M16=1,IF('Model inputs'!M16="","",'Model inputs'!M16=1))="",FALSE,IF(ISERROR('Model inputs'!M16=1),'Model inputs'!M16=1,IF('Model inputs'!M16="","",'Model inputs'!M16=1))),IF('Model inputs'!AB26="","",'Model inputs'!AB26),IF('Base vs Growth vs Downside key'!L17="","",'Base vs Growth vs Downside key'!L17))="",0,IF(IF(IF(ISERROR('Model inputs'!M16=1),'Model inputs'!M16=1,IF('Model inputs'!M16="","",'Model inputs'!M16=1))="",FALSE,IF(ISERROR('Model inputs'!M16=1),'Model inputs'!M16=1,IF('Model inputs'!M16="","",'Model inputs'!M16=1))),IF('Model inputs'!AB26="","",'Model inputs'!AB26),IF('Base vs Growth vs Downside key'!L17="","",'Base vs Growth vs Downside key'!L17)))+'Model inputs'!M18 -> 1518.8 | N17: =IF(IF(IF(IF(ISERROR('Model inputs'!N16=1),'Model inputs'!N16=1,IF('Model inputs'!N16="","",'Model inputs'!N16=1))="",FALSE,IF(ISERROR('Model inputs'!N16=1),'Model inputs'!N16=1,IF('Model inputs'!N16="","",'Model inputs'!N16=1))),IF('Model inputs'!AB26="","",'Model inputs'!AB26),IF('Base vs Growth vs Downside key'!M17="","",'Base vs Growth vs Downside key'!M17))="",0,IF(IF(IF(ISERROR('Model inputs'!N16=1),'Model inputs'!N16=1,IF('Model inputs'!N16="","",'Model inputs'!N16=1))="",FALSE,IF(ISERROR('Model inputs'!N16=1),'Model inputs'!N16=1,IF('Model inputs'!N16="","",'Model inputs'!N16=1))),IF('Model inputs'!AB26="","",'Model inputs'!AB26),IF('Base vs Growth vs Downside key'!M17="","",'Base vs Growth vs Downside key'!M17)))+'Model inputs'!N18 -> 20.32 | O17: =IF(IF(IF(IF(ISERROR('Model inputs'!O16=1),'Model inputs'!O16=1,IF('Model inputs'!O16="","",'Model inputs'!O16=1))="",FALSE,IF(ISERROR('Model inputs'!O16=1),'Model inputs'!O16=1,IF('Model inputs'!O16="","",'Model inputs'!O16=1))),IF('Model inputs'!AB26="","",'Model inputs'!AB26),IF('Base vs Growth vs Downside key'!N17="","",'Base vs Growth vs Downside key'!N17))="",0,IF(IF(IF(ISERROR('Model inputs'!O16=1),'Model inputs'!O16=1,IF('Model inputs'!O16="","",'Model inputs'!O16=1))="",FALSE,IF(ISERROR('Model inputs'!O16=1),'Model inputs'!O16=1,IF('Model inputs'!O16="","",'Model inputs'!O16=1))),IF('Model inputs'!AB26="","",'Model inputs'!AB26),IF('Base vs Growth vs Downside key'!N17="","",'Base vs Growth vs Downside key'!N17)))+'Model inputs'!O18 -> -1353.6 | P17: =IF(IF(IF(IF(ISERROR('Model inputs'!P16=1),'Model inputs'!P16=1,IF('Model inputs'!P16="","",'Model inputs'!P16=1))="",FALSE,IF(ISERROR('Model inputs'!P16=1),'Model inputs'!P16=1,IF('Model inputs'!P16="","",'Model inputs'!P16=1))),IF('Model inputs'!AB26="","",'Model inputs'!AB26),IF('Base vs Growth vs Downside key'!O17="","",'Base vs Growth vs Downside key'!O17))="",0,IF(IF(IF(ISERROR('Model inputs'!P16=1),'Model inputs'!P16=1,IF('Model inputs'!P16="","",'Model inputs'!P16=1))="",FALSE,IF(ISERROR('Model inputs'!P16=1),'Model inputs'!P16=1,IF('Model inputs'!P16="","",'Model inputs'!P16=1))),IF('Model inputs'!AB26="","",'Model inputs'!AB26),IF('Base vs Growth vs Downside key'!O17="","",'Base vs Growth vs Downside key'!O17)))+'Model inputs'!P18 -> -2654 | Q17: =IF(IF(IF(IF(ISERROR('Model inputs'!Q16=1),'Model inputs'!Q16=1,IF('Model inputs'!Q16="","",'Model inputs'!Q16=1))="",FALSE,IF(ISERROR('Model inputs'!Q16=1),'Model inputs'!Q16=1,IF('Model inputs'!Q16="","",'Model inputs'!Q16=1))),IF('Model inputs'!AB26="","",'Model inputs'!AB26),IF('Base vs Growth vs Downside key'!P17="","",'Base vs Growth vs Downside key'!P17))="",0,IF(IF(IF(ISERROR('Model inputs'!Q16=1),'Model inputs'!Q16=1,IF('Model inputs'!Q16="","",'Model inputs'!Q16=1))="",FALSE,IF(ISERROR('Model inputs'!Q16=1),'Model inputs'!Q16=1,IF('Model inputs'!Q16="","",'Model inputs'!Q16=1))),IF('Model inputs'!AB26="","",'Model inputs'!AB26),IF('Base vs Growth vs Downside key'!P17="","",'Base vs Growth vs Downside key'!P17)))+'Model inputs'!Q18 -> -3793.08 | R17: =IF(IF(IF(IF(ISERROR('Model inputs'!R16=1),'Model inputs'!R16=1,IF('Model inputs'!R16="","",'Model inputs'!R16=1))="",FALSE,IF(ISERROR('Model inputs'!R16=1),'Model inputs'!R16=1,IF('Model inputs'!R16="","",'Model inputs'!R16=1))),IF('Model inputs'!AB26="","",'Model inputs'!AB26),IF('Base vs Growth vs Downside key'!Q17="","",'Base vs Growth vs Downside key'!Q17))="",0,IF(IF(IF(ISERROR('Model inputs'!R16=1),'Model inputs'!R16=1,IF('Model inputs'!R16="","",'Model inputs'!R16=1))="",FALSE,IF(ISERROR('Model inputs'!R16=1),'Model inputs'!R16=1,IF('Model inputs'!R16="","",'Model inputs'!R16=1))),IF('Model inputs'!AB26="","",'Model inputs'!AB26),IF('Base vs Growth vs Downside key'!Q17="","",'Base vs Growth vs Downside key'!Q17)))+'Model inputs'!R18 -> -4858.64 | S17: =IF(IF(IF(IF(ISERROR('Model inputs'!S16=1),'Model inputs'!S16=1,IF('Model inputs'!S16="","",'Model inputs'!S16=1))="",FALSE,IF(ISERROR('Model inputs'!S16=1),'Model inputs'!S16=1,IF('Model inputs'!S16="","",'Model inputs'!S16=1))),IF('Model inputs'!AB26="","",'Model inputs'!AB26),IF('Base vs Growth vs Downside key'!R17="","",'Base vs Growth vs Downside key'!R17))="",0,IF(IF(IF(ISERROR('Model inputs'!S16=1),'Model inputs'!S16=1,IF('Model inputs'!S16="","",'Model inputs'!S16=1))="",FALSE,IF(ISERROR('Model inputs'!S16=1),'Model inputs'!S16=1,IF('Model inputs'!S16="","",'Model inputs'!S16=1))),IF('Model inputs'!AB26="","",'Model inputs'!AB26),IF('Base vs Growth vs Downside key'!R17="","",'Base vs Growth vs Downside key'!R17)))+'Model inputs'!S18 -> -5762.88 | T17: =IF(IF(IF(IF(ISERROR('Model inputs'!T16=1),'Model inputs'!T16=1,IF('Model inputs'!T16="","",'Model inputs'!T16=1))="",FALSE,IF(ISERROR('Model inputs'!T16=1),'Model inputs'!T16=1,IF('Model inputs'!T16="","",'Model inputs'!T16=1))),IF('Model inputs'!AB26="","",'Model inputs'!AB26),IF('Base vs Growth vs Downside key'!S17="","",'Base vs Growth vs Downside key'!S17))="",0,IF(IF(IF(ISERROR('Model inputs'!T16=1),'Model inputs'!T16=1,IF('Model inputs'!T16="","",'Model inputs'!T16=1))="",FALSE,IF(ISERROR('Model inputs'!T16=1),'Model inputs'!T16=1,IF('Model inputs'!T16="","",'Model inputs'!T16=1))),IF('Model inputs'!AB26="","",'Model inputs'!AB26),IF('Base vs Growth vs Downside key'!S17="","",'Base vs Growth vs Downside key'!S17)))+'Model inputs'!T18 -> -6593.6 | U17: =IF(IF(IF(IF(ISERROR('Model inputs'!U16=1),'Model inputs'!U16=1,IF('Model inputs'!U16="","",'Model inputs'!U16=1))="",FALSE,IF(ISERROR('Model inputs'!U16=1),'Model inputs'!U16=1,IF('Model inputs'!U16="","",'Model inputs'!U16=1))),IF('Model inputs'!AB26="","",'Model inputs'!AB26),IF('Base vs Growth vs Downside key'!T17="","",'Base vs Growth vs Downside key'!T17))="",0,IF(IF(IF(ISERROR('Model inputs'!U16=1),'Model inputs'!U16=1,IF('Model inputs'!U16="","",'Model inputs'!U16=1))="",FALSE,IF(ISERROR('Model inputs'!U16=1),'Model inputs'!U16=1,IF('Model inputs'!U16="","",'Model inputs'!U16=1))),IF('Model inputs'!AB26="","",'Model inputs'!AB26),IF('Base vs Growth vs Downside key'!T17="","",'Base vs Growth vs Downside key'!T17)))+'Model inputs'!U18 -> -7263 | V17: =IF(IF(IF(IF(ISERROR('Model inputs'!V16=1),'Model inputs'!V16=1,IF('Model inputs'!V16="","",'Model inputs'!V16=1))="",FALSE,IF(ISERROR('Model inputs'!V16=1),'Model inputs'!V16=1,IF('Model inputs'!V16="","",'Model inputs'!V16=1))),IF('Model inputs'!AB26="","",'Model inputs'!AB26),IF('Base vs Growth vs Downside key'!U17="","",'Base vs Growth vs Downside key'!U17))="",0,IF(IF(IF(ISERROR('Model inputs'!V16=1),'Model inputs'!V16=1,IF('Model inputs'!V16="","",'Model inputs'!V16=1))="",FALSE,IF(ISERROR('Model inputs'!V16=1),'Model inputs'!V16=1,IF('Model inputs'!V16="","",'Model inputs'!V16=1))),IF('Model inputs'!AB26="","",'Model inputs'!AB26),IF('Base vs Growth vs Downside key'!U17="","",'Base vs Growth vs Downside key'!U17)))+'Model inputs'!V18 -> -7734.32 | W17: =IF(IF(IF(IF(ISERROR('Model inputs'!W16=1),'Model inputs'!W16=1,IF('Model inputs'!W16="","",'Model inputs'!W16=1))="",FALSE,IF(ISERROR('Model inputs'!W16=1),'Model inputs'!W16=1,IF('Model inputs'!W16="","",'Model inputs'!W16=1))),IF('Model inputs'!AB26="","",'Model inputs'!AB26),IF('Base vs Growth vs Downside key'!V17="","",'Base vs Growth vs Downside key'!V17))="",0,IF(IF(IF(ISERROR('Model inputs'!W16=1),'Model inputs'!W16=1,IF('Model inputs'!W16="","",'Model inputs'!W16=1))="",FALSE,IF(ISERROR('Model inputs'!W16=1),'Model inputs'!W16=1,IF('Model inputs'!W16="","",'Model inputs'!W16=1))),IF('Model inputs'!AB26="","",'Model inputs'!AB26),IF('Base vs Growth vs Downside key'!V17="","",'Base vs Growth vs Downside key'!V17)))+'Model inputs'!W18 -> -8132.12 | X17: =IF(IF(IF(IF(ISERROR('Model inputs'!X16=1),'Model inputs'!X16=1,IF('Model inputs'!X16="","",'Model inputs'!X16=1))="",FALSE,IF(ISERROR('Model inputs'!X16=1),'Model inputs'!X16=1,IF('Model inputs'!X16="","",'Model inputs'!X16=1))),IF('Model inputs'!AB26="","",'Model inputs'!AB26),IF('Base vs Growth vs Downside key'!W17="","",'Base vs Growth vs Downside key'!W17))="",0,IF(IF(IF(ISERROR('Model inputs'!X16=1),'Model inputs'!X16=1,IF('Model inputs'!X16="","",'Model inputs'!X16=1))="",FALSE,IF(ISERROR('Model inputs'!X16=1),'Model inputs'!X16=1,IF('Model inputs'!X16="","",'Model inputs'!X16=1))),IF('Model inputs'!AB26="","",'Model inputs'!AB26),IF('Base vs Growth vs Downside key'!W17="","",'Base vs Growth vs Downside key'!W17)))+'Model inputs'!X18 -> -8368.6 | Y17: =IF(IF(IF(IF(ISERROR('Model inputs'!Y16=1),'Model inputs'!Y16=1,IF('Model inputs'!Y16="","",'Model inputs'!Y16=1))="",FALSE,IF(ISERROR('Model inputs'!Y16=1),'Model inputs'!Y16=1,IF('Model inputs'!Y16="","",'Model inputs'!Y16=1))),IF('Model inputs'!AB26="","",'Model inputs'!AB26),IF('Base vs Growth vs Downside key'!X17="","",'Base vs Growth vs Downside key'!X17))="",0,IF(IF(IF(ISERROR('Model inputs'!Y16=1),'Model inputs'!Y16=1,IF('Model inputs'!Y16="","",'Model inputs'!Y16=1))="",FALSE,IF(ISERROR('Model inputs'!Y16=1),'Model inputs'!Y16=1,IF('Model inputs'!Y16="","",'Model inputs'!Y16=1))),IF('Model inputs'!AB26="","",'Model inputs'!AB26),IF('Base vs Growth vs Downside key'!X17="","",'Base vs Growth vs Downside key'!X17)))+'Model inputs'!Y18 -> -8531.56
A18: Ending cash > Growth | B18: =IF(IF(IF(IF(ISERROR('Model inputs'!B17=1),'Model inputs'!B17=1,IF('Model inputs'!B17="","",'Model inputs'!B17=1))="",FALSE,IF(ISERROR('Model inputs'!B17=1),'Model inputs'!B17=1,IF('Model inputs'!B17="","",'Model inputs'!B17=1))),IF('Model inputs'!AB27="","",'Model inputs'!AB27),IF('Model inputs'!AA13="","",'Model inputs'!AA13))="",0,IF(IF(IF(ISERROR('Model inputs'!B17=1),'Model inputs'!B17=1,IF('Model inputs'!B17="","",'Model inputs'!B17=1))="",FALSE,IF(ISERROR('Model inputs'!B17=1),'Model inputs'!B17=1,IF('Model inputs'!B17="","",'Model inputs'!B17=1))),IF('Model inputs'!AB27="","",'Model inputs'!AB27),IF('Model inputs'!AA13="","",'Model inputs'!AA13)))+'Model inputs'!B19 -> 22884.8 | C18: =IF(IF(IF(IF(ISERROR('Model inputs'!C17=1),'Model inputs'!C17=1,IF('Model inputs'!C17="","",'Model inputs'!C17=1))="",FALSE,IF(ISERROR('Model inputs'!C17=1),'Model inputs'!C17=1,IF('Model inputs'!C17="","",'Model inputs'!C17=1))),IF('Model inputs'!AB27="","",'Model inputs'!AB27),IF('Base vs Growth vs Downside key'!B18="","",'Base vs Growth vs Downside key'!B18))="",0,IF(IF(IF(ISERROR('Model inputs'!C17=1),'Model inputs'!C17=1,IF('Model inputs'!C17="","",'Model inputs'!C17=1))="",FALSE,IF(ISERROR('Model inputs'!C17=1),'Model inputs'!C17=1,IF('Model inputs'!C17="","",'Model inputs'!C17=1))),IF('Model inputs'!AB27="","",'Model inputs'!AB27),IF('Base vs Growth vs Downside key'!B18="","",'Base vs Growth vs Downside key'!B18)))+'Model inputs'!C19 -> 20769.6 | D18: =IF(IF(IF(IF(ISERROR('Model inputs'!D17=1),'Model inputs'!D17=1,IF('Model inputs'!D17="","",'Model inputs'!D17=1))="",FALSE,IF(ISERROR('Model inputs'!D17=1),'Model inputs'!D17=1,IF('Model inputs'!D17="","",'Model inputs'!D17=1))),IF('Model inputs'!AB27="","",'Model inputs'!AB27),IF('Base vs Growth vs Downside key'!C18="","",'Base vs Growth vs Downside key'!C18))="",0,IF(IF(IF(ISERROR('Model inputs'!D17=1),'Model inputs'!D17=1,IF('Model inputs'!D17="","",'Model inputs'!D17=1))="",FALSE,IF(ISERROR('Model inputs'!D17=1),'Model inputs'!D17=1,IF('Model inputs'!D17="","",'Model inputs'!D17=1))),IF('Model inputs'!AB27="","",'Model inputs'!AB27),IF('Base vs Growth vs Downside key'!C18="","",'Base vs Growth vs Downside key'!C18)))+'Model inputs'!D19 -> 18654.4 | E18: =IF(IF(IF(IF(ISERROR('Model inputs'!E17=1),'Model inputs'!E17=1,IF('Model inputs'!E17="","",'Model inputs'!E17=1))="",FALSE,IF(ISERROR('Model inputs'!E17=1),'Model inputs'!E17=1,IF('Model inputs'!E17="","",'Model inputs'!E17=1))),IF('Model inputs'!AB27="","",'Model inputs'!AB27),IF('Base vs Growth vs Downside key'!D18="","",'Base vs Growth vs Downside key'!D18))="",0,IF(IF(IF(ISERROR('Model inputs'!E17=1),'Model inputs'!E17=1,IF('Model inputs'!E17="","",'Model inputs'!E17=1))="",FALSE,IF(ISERROR('Model inputs'!E17=1),'Model inputs'!E17=1,IF('Model inputs'!E17="","",'Model inputs'!E17=1))),IF('Model inputs'!AB27="","",'Model inputs'!AB27),IF('Base vs Growth vs Downside key'!D18="","",'Base vs Growth vs Downside key'!D18)))+'Model inputs'!E19 -> 17033.696 | F18: =IF(IF(IF(IF(ISERROR('Model inputs'!F17=1),'Model inputs'!F17=1,IF('Model inputs'!F17="","",'Model inputs'!F17=1))="",FALSE,IF(ISERROR('Model inputs'!F17=1),'Model inputs'!F17=1,IF('Model inputs'!F17="","",'Model inputs'!F17=1))),IF('Model inputs'!AB27="","",'Model inputs'!AB27),IF('Base vs Growth vs Downside key'!E18="","",'Base vs Growth vs Downside key'!E18))="",0,IF(IF(IF(ISERROR('Model inputs'!F17=1),'Model inputs'!F17=1,IF('Model inputs'!F17="","",'Model inputs'!F17=1))="",FALSE,IF(ISERROR('Model inputs'!F17=1),'Model inputs'!F17=1,IF('Model inputs'!F17="","",'Model inputs'!F17=1))),IF('Model inputs'!AB27="","",'Model inputs'!AB27),IF('Base vs Growth vs Downside key'!E18="","",'Base vs Growth vs Downside key'!E18)))+'Model inputs'!F19 -> 15708.24 | G18: =IF(IF(IF(IF(ISERROR('Model inputs'!G17=1),'Model inputs'!G17=1,IF('Model inputs'!G17="","",'Model inputs'!G17=1))="",FALSE,IF(ISERROR('Model inputs'!G17=1),'Model inputs'!G17=1,IF('Model inputs'!G17="","",'Model inputs'!G17=1))),IF('Model inputs'!AB27="","",'Model inputs'!AB27),IF('Base vs Growth vs Downside key'!F18="","",'Base vs Growth vs Downside key'!F18))="",0,IF(IF(IF(ISERROR('Model inputs'!G17=1),'Model inputs'!G17=1,IF('Model inputs'!G17="","",'Model inputs'!G17=1))="",FALSE,IF(ISERROR('Model inputs'!G17=1),'Model inputs'!G17=1,IF('Model inputs'!G17="","",'Model inputs'!G17=1))),IF('Model inputs'!AB27="","",'Model inputs'!AB27),IF('Base vs Growth vs Downside key'!F18="","",'Base vs Growth vs Downside key'!F18)))+'Model inputs'!G19 -> 14877.28 | H18: =IF(IF(IF(IF(ISERROR('Model inputs'!H17=1),'Model inputs'!H17=1,IF('Model inputs'!H17="","",'Model inputs'!H17=1))="",FALSE,IF(ISERROR('Model inputs'!H17=1),'Model inputs'!H17=1,IF('Model inputs'!H17="","",'Model inputs'!H17=1))),IF('Model inputs'!AB27="","",'Model inputs'!AB27),IF('Base vs Growth vs Downside key'!G18="","",'Base vs Growth vs Downside key'!G18))="",0,IF(IF(IF(ISERROR('Model inputs'!H17=1),'Model inputs'!H17=1,IF('Model inputs'!H17="","",'Model inputs'!H17=1))="",FALSE,IF(ISERROR('Model inputs'!H17=1),'Model inputs'!H17=1,IF('Model inputs'!H17="","",'Model inputs'!H17=1))),IF('Model inputs'!AB27="","",'Model inputs'!AB27),IF('Base vs Growth vs Downside key'!G18="","",'Base vs Growth vs Downside key'!G18)))+'Model inputs'!H19 -> 14614.628 | I18: =IF(IF(IF(IF(ISERROR('Model inputs'!I17=1),'Model inputs'!I17=1,IF('Model inputs'!I17="","",'Model inputs'!I17=1))="",FALSE,IF(ISERROR('Model inputs'!I17=1),'Model inputs'!I17=1,IF('Model inputs'!I17="","",'Model inputs'!I17=1))),IF('Model inputs'!AB27="","",'Model inputs'!AB27),IF('Base vs Growth vs Downside key'!H18="","",'Base vs Growth vs Downside key'!H18))="",0,IF(IF(IF(ISERROR('Model inputs'!I17=1),'Model inputs'!I17=1,IF('Model inputs'!I17="","",'Model inputs'!I17=1))="",FALSE,IF(ISERROR('Model inputs'!I17=1),'Model inputs'!I17=1,IF('Model inputs'!I17="","",'Model inputs'!I17=1))),IF('Model inputs'!AB27="","",'Model inputs'!AB27),IF('Base vs Growth vs Downside key'!H18="","",'Base vs Growth vs Downside key'!H18)))+'Model inputs'!I19 -> 14920.284 | J18: =IF(IF(IF(IF(ISERROR('Model inputs'!J17=1),'Model inputs'!J17=1,IF('Model inputs'!J17="","",'Model inputs'!J17=1))="",FALSE,IF(ISERROR('Model inputs'!J17=1),'Model inputs'!J17=1,IF('Model inputs'!J17="","",'Model inputs'!J17=1))),IF('Model inputs'!AB27="","",'Model inputs'!AB27),IF('Base vs Growth vs Downside key'!I18="","",'Base vs Growth vs Downside key'!I18))="",0,IF(IF(IF(ISERROR('Model inputs'!J17=1),'Model inputs'!J17=1,IF('Model inputs'!J17="","",'Model inputs'!J17=1))="",FALSE,IF(ISERROR('Model inputs'!J17=1),'Model inputs'!J17=1,IF('Model inputs'!J17="","",'Model inputs'!J17=1))),IF('Model inputs'!AB27="","",'Model inputs'!AB27),IF('Base vs Growth vs Downside key'!I18="","",'Base vs Growth vs Downside key'!I18)))+'Model inputs'!J19 -> 15868.06 | K18: =IF(IF(IF(IF(ISERROR('Model inputs'!K17=1),'Model inputs'!K17=1,IF('Model inputs'!K17="","",'Model inputs'!K17=1))="",FALSE,IF(ISERROR('Model inputs'!K17=1),'Model inputs'!K17=1,IF('Model inputs'!K17="","",'Model inputs'!K17=1))),IF('Model inputs'!AB27="","",'Model inputs'!AB27),IF('Base vs Growth vs Downside key'!J18="","",'Base vs Growth vs Downside key'!J18))="",0,IF(IF(IF(ISERROR('Model inputs'!K17=1),'Model inputs'!K17=1,IF('Model inputs'!K17="","",'Model inputs'!K17=1))="",FALSE,IF(ISERROR('Model inputs'!K17=1),'Model inputs'!K17=1,IF('Model inputs'!K17="","",'Model inputs'!K17=1))),IF('Model inputs'!AB27="","",'Model inputs'!AB27),IF('Base vs Growth vs Downside key'!J18="","",'Base vs Growth vs Downside key'!J18)))+'Model inputs'!K19 -> 17384.144 | L18: =IF(IF(IF(IF(ISERROR('Model inputs'!L17=1),'Model inputs'!L17=1,IF('Model inputs'!L17="","",'Model inputs'!L17=1))="",FALSE,IF(ISERROR('Model inputs'!L17=1),'Model inputs'!L17=1,IF('Model inputs'!L17="","",'Model inputs'!L17=1))),IF('Model inputs'!AB27="","",'Model inputs'!AB27),IF('Base vs Growth vs Downside key'!K18="","",'Base vs Growth vs Downside key'!K18))="",0,IF(IF(IF(ISERROR('Model inputs'!L17=1),'Model inputs'!L17=1,IF('Model inputs'!L17="","",'Model inputs'!L17=1))="",FALSE,IF(ISERROR('Model inputs'!L17=1),'Model inputs'!L17=1,IF('Model inputs'!L17="","",'Model inputs'!L17=1))),IF('Model inputs'!AB27="","",'Model inputs'!AB27),IF('Base vs Growth vs Downside key'!K18="","",'Base vs Growth vs Downside key'!K18)))+'Model inputs'!L19 -> 19468.536 | M18: =IF(IF(IF(IF(ISERROR('Model inputs'!M17=1),'Model inputs'!M17=1,IF('Model inputs'!M17="","",'Model inputs'!M17=1))="",FALSE,IF(ISERROR('Model inputs'!M17=1),'Model inputs'!M17=1,IF('Model inputs'!M17="","",'Model inputs'!M17=1))),IF('Model inputs'!AB27="","",'Model inputs'!AB27),IF('Base vs Growth vs Downside key'!L18="","",'Base vs Growth vs Downside key'!L18))="",0,IF(IF(IF(ISERROR('Model inputs'!M17=1),'Model inputs'!M17=1,IF('Model inputs'!M17="","",'Model inputs'!M17=1))="",FALSE,IF(ISERROR('Model inputs'!M17=1),'Model inputs'!M17=1,IF('Model inputs'!M17="","",'Model inputs'!M17=1))),IF('Model inputs'!AB27="","",'Model inputs'!AB27),IF('Base vs Growth vs Downside key'!L18="","",'Base vs Growth vs Downside key'!L18)))+'Model inputs'!M19 -> 22121.236 | N18: =IF(IF(IF(IF(ISERROR('Model inputs'!N17=1),'Model inputs'!N17=1,IF('Model inputs'!N17="","",'Model inputs'!N17=1))="",FALSE,IF(ISERROR('Model inputs'!N17=1),'Model inputs'!N17=1,IF('Model inputs'!N17="","",'Model inputs'!N17=1))),IF('Model inputs'!AB27="","",'Model inputs'!AB27),IF('Base vs Growth vs Downside key'!M18="","",'Base vs Growth vs Downside key'!M18))="",0,IF(IF(IF(ISERROR('Model inputs'!N17=1),'Model inputs'!N17=1,IF('Model inputs'!N17="","",'Model inputs'!N17=1))="",FALSE,IF(ISERROR('Model inputs'!N17=1),'Model inputs'!N17=1,IF('Model inputs'!N17="","",'Model inputs'!N17=1))),IF('Model inputs'!AB27="","",'Model inputs'!AB27),IF('Base vs Growth vs Downside key'!M18="","",'Base vs Growth vs Downside key'!M18)))+'Model inputs'!N19 -> 25416.056 | O18: =IF(IF(IF(IF(ISERROR('Model inputs'!O17=1),'Model inputs'!O17=1,IF('Model inputs'!O17="","",'Model inputs'!O17=1))="",FALSE,IF(ISERROR('Model inputs'!O17=1),'Model inputs'!O17=1,IF('Model inputs'!O17="","",'Model inputs'!O17=1))),IF('Model inputs'!AB27="","",'Model inputs'!AB27),IF('Base vs Growth vs Downside key'!N18="","",'Base vs Growth vs Downside key'!N18))="",0,IF(IF(IF(ISERROR('Model inputs'!O17=1),'Model inputs'!O17=1,IF('Model inputs'!O17="","",'Model inputs'!O17=1))="",FALSE,IF(ISERROR('Model inputs'!O17=1),'Model inputs'!O17=1,IF('Model inputs'!O17="","",'Model inputs'!O17=1))),IF('Model inputs'!AB27="","",'Model inputs'!AB27),IF('Base vs Growth vs Downside key'!N18="","",'Base vs Growth vs Downside key'!N18)))+'Model inputs'!O19 -> 29699.868 | P18: =IF(IF(IF(IF(ISERROR('Model inputs'!P17=1),'Model inputs'!P17=1,IF('Model inputs'!P17="","",'Model inputs'!P17=1))="",FALSE,IF(ISERROR('Model inputs'!P17=1),'Model inputs'!P17=1,IF('Model inputs'!P17="","",'Model inputs'!P17=1))),IF('Model inputs'!AB27="","",'Model inputs'!AB27),IF('Base vs Growth vs Downside key'!O18="","",'Base vs Growth vs Downside key'!O18))="",0,IF(IF(IF(ISERROR('Model inputs'!P17=1),'Model inputs'!P17=1,IF('Model inputs'!P17="","",'Model inputs'!P17=1))="",FALSE,IF(ISERROR('Model inputs'!P17=1),'Model inputs'!P17=1,IF('Model inputs'!P17="","",'Model inputs'!P17=1))),IF('Model inputs'!AB27="","",'Model inputs'!AB27),IF('Base vs Growth vs Downside key'!O18="","",'Base vs Growth vs Downside key'!O18)))+'Model inputs'!P19 -> 34625.8 | Q18: =IF(IF(IF(IF(ISERROR('Model inputs'!Q17=1),'Model inputs'!Q17=1,IF('Model inputs'!Q17="","",'Model inputs'!Q17=1))="",FALSE,IF(ISERROR('Model inputs'!Q17=1),'Model inputs'!Q17=1,IF('Model inputs'!Q17="","",'Model inputs'!Q17=1))),IF('Model inputs'!AB27="","",'Model inputs'!AB27),IF('Base vs Growth vs Downside key'!P18="","",'Base vs Growth vs Downside key'!P18))="",0,IF(IF(IF(ISERROR('Model inputs'!Q17=1),'Model inputs'!Q17=1,IF('Model inputs'!Q17="","",'Model inputs'!Q17=1))="",FALSE,IF(ISERROR('Model inputs'!Q17=1),'Model inputs'!Q17=1,IF('Model inputs'!Q17="","",'Model inputs'!Q17=1))),IF('Model inputs'!AB27="","",'Model inputs'!AB27),IF('Base vs Growth vs Downside key'!P18="","",'Base vs Growth vs Downside key'!P18)))+'Model inputs'!Q19 -> 40540.724 | R18: =IF(IF(IF(IF(ISERROR('Model inputs'!R17=1),'Model inputs'!R17=1,IF('Model inputs'!R17="","",'Model inputs'!R17=1))="",FALSE,IF(ISERROR('Model inputs'!R17=1),'Model inputs'!R17=1,IF('Model inputs'!R17="","",'Model inputs'!R17=1))),IF('Model inputs'!AB27="","",'Model inputs'!AB27),IF('Base vs Growth vs Downside key'!Q18="","",'Base vs Growth vs Downside key'!Q18))="",0,IF(IF(IF(ISERROR('Model inputs'!R17=1),'Model inputs'!R17=1,IF('Model inputs'!R17="","",'Model inputs'!R17=1))="",FALSE,IF(ISERROR('Model inputs'!R17=1),'Model inputs'!R17=1,IF('Model inputs'!R17="","",'Model inputs'!R17=1))),IF('Model inputs'!AB27="","",'Model inputs'!AB27),IF('Base vs Growth vs Downside key'!Q18="","",'Base vs Growth vs Downside key'!Q18)))+'Model inputs'!R19 -> 47097.768 | S18: =IF(IF(IF(IF(ISERROR('Model inputs'!S17=1),'Model inputs'!S17=1,IF('Model inputs'!S17="","",'Model inputs'!S17=1))="",FALSE,IF(ISERROR('Model inputs'!S17=1),'Model inputs'!S17=1,IF('Model inputs'!S17="","",'Model inputs'!S17=1))),IF('Model inputs'!AB27="","",'Model inputs'!AB27),IF('Base vs Growth vs Downside key'!R18="","",'Base vs Growth vs Downside key'!R18))="",0,IF(IF(IF(ISERROR('Model inputs'!S17=1),'Model inputs'!S17=1,IF('Model inputs'!S17="","",'Model inputs'!S17=1))="",FALSE,IF(ISERROR('Model inputs'!S17=1),'Model inputs'!S17=1,IF('Model inputs'!S17="","",'Model inputs'!S17=1))),IF('Model inputs'!AB27="","",'Model inputs'!AB27),IF('Base vs Growth vs Downside key'!R18="","",'Base vs Growth vs Downside key'!R18)))+'Model inputs'!S19 -> 54643.804 | T18: =IF(IF(IF(IF(ISERROR('Model inputs'!T17=1),'Model inputs'!T17=1,IF('Model inputs'!T17="","",'Model inputs'!T17=1))="",FALSE,IF(ISERROR('Model inputs'!T17=1),'Model inputs'!T17=1,IF('Model inputs'!T17="","",'Model inputs'!T17=1))),IF('Model inputs'!AB27="","",'Model inputs'!AB27),IF('Base vs Growth vs Downside key'!S18="","",'Base vs Growth vs Downside key'!S18))="",0,IF(IF(IF(ISERROR('Model inputs'!T17=1),'Model inputs'!T17=1,IF('Model inputs'!T17="","",'Model inputs'!T17=1))="",FALSE,IF(ISERROR('Model inputs'!T17=1),'Model inputs'!T17=1,IF('Model inputs'!T17="","",'Model inputs'!T17=1))),IF('Model inputs'!AB27="","",'Model inputs'!AB27),IF('Base vs Growth vs Downside key'!S18="","",'Base vs Growth vs Downside key'!S18)))+'Model inputs'!T19 -> 62831.96 | U18: =IF(IF(IF(IF(ISERROR('Model inputs'!U17=1),'Model inputs'!U17=1,IF('Model inputs'!U17="","",'Model inputs'!U17=1))="",FALSE,IF(ISERROR('Model inputs'!U17=1),'Model inputs'!U17=1,IF('Model inputs'!U17="","",'Model inputs'!U17=1))),IF('Model inputs'!AB27="","",'Model inputs'!AB27),IF('Base vs Growth vs Downside key'!T18="","",'Base vs Growth vs Downside key'!T18))="",0,IF(IF(IF(ISERROR('Model inputs'!U17=1),'Model inputs'!U17=1,IF('Model inputs'!U17="","",'Model inputs'!U17=1))="",FALSE,IF(ISERROR('Model inputs'!U17=1),'Model inputs'!U17=1,IF('Model inputs'!U17="","",'Model inputs'!U17=1))),IF('Model inputs'!AB27="","",'Model inputs'!AB27),IF('Base vs Growth vs Downside key'!T18="","",'Base vs Growth vs Downside key'!T18)))+'Model inputs'!U19 -> 71662.236 | V18: =IF(IF(IF(IF(ISERROR('Model inputs'!V17=1),'Model inputs'!V17=1,IF('Model inputs'!V17="","",'Model inputs'!V17=1))="",FALSE,IF(ISERROR('Model inputs'!V17=1),'Model inputs'!V17=1,IF('Model inputs'!V17="","",'Model inputs'!V17=1))),IF('Model inputs'!AB27="","",'Model inputs'!AB27),IF('Base vs Growth vs Downside key'!U18="","",'Base vs Growth vs Downside key'!U18))="",0,IF(IF(IF(ISERROR('Model inputs'!V17=1),'Model inputs'!V17=1,IF('Model inputs'!V17="","",'Model inputs'!V17=1))="",FALSE,IF(ISERROR('Model inputs'!V17=1),'Model inputs'!V17=1,IF('Model inputs'!V17="","",'Model inputs'!V17=1))),IF('Model inputs'!AB27="","",'Model inputs'!AB27),IF('Base vs Growth vs Downside key'!U18="","",'Base vs Growth vs Downside key'!U18)))+'Model inputs'!V19 -> 81481.504 | W18: =IF(IF(IF(IF(ISERROR('Model inputs'!W17=1),'Model inputs'!W17=1,IF('Model inputs'!W17="","",'Model inputs'!W17=1))="",FALSE,IF(ISERROR('Model inputs'!W17=1),'Model inputs'!W17=1,IF('Model inputs'!W17="","",'Model inputs'!W17=1))),IF('Model inputs'!AB27="","",'Model inputs'!AB27),IF('Base vs Growth vs Downside key'!V18="","",'Base vs Growth vs Downside key'!V18))="",0,IF(IF(IF(ISERROR('Model inputs'!W17=1),'Model inputs'!W17=1,IF('Model inputs'!W17="","",'Model inputs'!W17=1))="",FALSE,IF(ISERROR('Model inputs'!W17=1),'Model inputs'!W17=1,IF('Model inputs'!W17="","",'Model inputs'!W17=1))),IF('Model inputs'!AB27="","",'Model inputs'!AB27),IF('Base vs Growth vs Downside key'!V18="","",'Base vs Growth vs Downside key'!V18)))+'Model inputs'!W19 -> 91942.892 | X18: =IF(IF(IF(IF(ISERROR('Model inputs'!X17=1),'Model inputs'!X17=1,IF('Model inputs'!X17="","",'Model inputs'!X17=1))="",FALSE,IF(ISERROR('Model inputs'!X17=1),'Model inputs'!X17=1,IF('Model inputs'!X17="","",'Model inputs'!X17=1))),IF('Model inputs'!AB27="","",'Model inputs'!AB27),IF('Base vs Growth vs Downside key'!W18="","",'Base vs Growth vs Downside key'!W18))="",0,IF(IF(IF(ISERROR('Model inputs'!X17=1),'Model inputs'!X17=1,IF('Model inputs'!X17="","",'Model inputs'!X17=1))="",FALSE,IF(ISERROR('Model inputs'!X17=1),'Model inputs'!X17=1,IF('Model inputs'!X17="","",'Model inputs'!X17=1))),IF('Model inputs'!AB27="","",'Model inputs'!AB27),IF('Base vs Growth vs Downside key'!W18="","",'Base vs Growth vs Downside key'!W18)))+'Model inputs'!X19 -> 103393.27 | Y18: =IF(IF(IF(IF(ISERROR('Model inputs'!Y17=1),'Model inputs'!Y17=1,IF('Model inputs'!Y17="","",'Model inputs'!Y17=1))="",FALSE,IF(ISERROR('Model inputs'!Y17=1),'Model inputs'!Y17=1,IF('Model inputs'!Y17="","",'Model inputs'!Y17=1))),IF('Model inputs'!AB27="","",'Model inputs'!AB27),IF('Base vs Growth vs Downside key'!X18="","",'Base vs Growth vs Downside key'!X18))="",0,IF(IF(IF(ISERROR('Model inputs'!Y17=1),'Model inputs'!Y17=1,IF('Model inputs'!Y17="","",'Model inputs'!Y17=1))="",FALSE,IF(ISERROR('Model inputs'!Y17=1),'Model inputs'!Y17=1,IF('Model inputs'!Y17="","",'Model inputs'!Y17=1))),IF('Model inputs'!AB27="","",'Model inputs'!AB27),IF('Base vs Growth vs Downside key'!X18="","",'Base vs Growth vs Downside key'!X18)))+'Model inputs'!Y19 -> 115485.77
A19: Ending cash > delta | B19: ='Base vs Growth vs Downside key'!B18-'Base vs Growth vs Downside key'!B17 -> 0 | C19: ='Base vs Growth vs Downside key'!C18-'Base vs Growth vs Downside key'!C17 -> 0 | D19: ='Base vs Growth vs Downside key'!D18-'Base vs Growth vs Downside key'!D17 -> 0 | E19: ='Base vs Growth vs Downside key'!E18-'Base vs Growth vs Downside key'!E17 -> 494.496 | F19: ='Base vs Growth vs Downside key'!F18-'Base vs Growth vs Downside key'!F17 -> 1284.24 | G19: ='Base vs Growth vs Downside key'!G18-'Base vs Growth vs Downside key'!G17 -> 2568.48 | H19: ='Base vs Growth vs Downside key'!H18-'Base vs Growth vs Downside key'!H17 -> 4347.508 | I19: ='Base vs Growth vs Downside key'!I18-'Base vs Growth vs Downside key'!I17 -> 6570.284 | ... Y19: ='Base vs Growth vs Downside key'!Y18-'Base vs Growth vs Downside key'!Y17 -> 124017.33
A20: Months of runway | B20: =IF(IF(IF(ISERROR('Base vs Growth vs Downside key'!B14>0),'Base vs Growth vs Downside key'!B14>0,IF('Base vs Growth vs Downside key'!B14="","",'Base vs Growth vs Downside key'!B14>0))="",FALSE,IF(ISERROR('Base vs Growth vs Downside key'!B14>0),'Base vs Growth vs Downside key'!B14>0,IF('Base vs Growth vs Downside key'!B14="","",'Base vs Growth vs Downside key'!B14>0))),'Base vs Growth vs Downside key'!B17/'Base vs Growth vs Downside key'!B14,"") -> 10.819213 | C20: =IF(IF(IF(ISERROR('Base vs Growth vs Downside key'!C14>0),'Base vs Growth vs Downside key'!C14>0,IF('Base vs Growth vs Downside key'!C14="","",'Base vs Growth vs Downside key'!C14>0))="",FALSE,IF(ISERROR('Base vs Growth vs Downside key'!C14>0),'Base vs Growth vs Downside key'!C14>0,IF('Base vs Growth vs Downside key'!C14="","",'Base vs Growth vs Downside key'!C14>0))),'Base vs Growth vs Downside key'!C17/'Base vs Growth vs Downside key'!C14,"") -> 9.8192133 | D20: =IF(IF(IF(ISERROR('Base vs Growth vs Downside key'!D14>0),'Base vs Growth vs Downside key'!D14>0,IF('Base vs Growth vs Downside key'!D14="","",'Base vs Growth vs Downside key'!D14>0))="",FALSE,IF(ISERROR('Base vs Growth vs Downside key'!D14>0),'Base vs Growth vs Downside key'!D14>0,IF('Base vs Growth vs Downside key'!D14="","",'Base vs Growth vs Downside key'!D14>0))),'Base vs Growth vs Downside key'!D17/'Base vs Growth vs Downside key'!D14,"") -> 8.8192133 | E20: =IF(IF(IF(ISERROR('Base vs Growth vs Downside key'!E14>0),'Base vs Growth vs Downside key'!E14>0,IF('Base vs Growth vs Downside key'!E14="","",'Base vs Growth vs Downside key'!E14>0))="",FALSE,IF(ISERROR('Base vs Growth vs Downside key'!E14>0),'Base vs Growth vs Downside key'!E14>0,IF('Base vs Growth vs Downside key'!E14="","",'Base vs Growth vs Downside key'!E14>0))),'Base vs Growth vs Downside key'!E17/'Base vs Growth vs Downside key'!E14,"") -> 7.8192133 | F20: =IF(IF(IF(ISERROR('Base vs Growth vs Downside key'!F14>0),'Base vs Growth vs Downside key'!F14>0,IF('Base vs Growth vs Downside key'!F14="","",'Base vs Growth vs Downside key'!F14>0))="",FALSE,IF(ISERROR('Base vs Growth vs Downside key'!F14>0),'Base vs Growth vs Downside key'!F14>0,IF('Base vs Growth vs Downside key'!F14="","",'Base vs Growth vs Downside key'!F14>0))),'Base vs Growth vs Downside key'!F17/'Base vs Growth vs Downside key'!F14,"") -> 6.8192133 | G20: =IF(IF(IF(ISERROR('Base vs Growth vs Downside key'!G14>0),'Base vs Growth vs Downside key'!G14>0,IF('Base vs Growth vs Downside key'!G14="","",'Base vs Growth vs Downside key'!G14>0))="",FALSE,IF(ISERROR('Base vs Growth vs Downside key'!G14>0),'Base vs Growth vs Downside key'!G14>0,IF('Base vs Growth vs Downside key'!G14="","",'Base vs Growth vs Downside key'!G14>0))),'Base vs Growth vs Downside key'!G17/'Base vs Growth vs Downside key'!G14,"") -> 5.8192133 | H20: =IF(IF(IF(ISERROR('Base vs Growth vs Downside key'!H14>0),'Base vs Growth vs Downside key'!H14>0,IF('Base vs Growth vs Downside key'!H14="","",'Base vs Growth vs Downside key'!H14>0))="",FALSE,IF(ISERROR('Base vs Growth vs Downside key'!H14>0),'Base vs Growth vs Downside key'!H14>0,IF('Base vs Growth vs Downside key'!H14="","",'Base vs Growth vs Downside key'!H14>0))),'Base vs Growth vs Downside key'!H17/'Base vs Growth vs Downside key'!H14,"") -> 5.0287606 | I20: =IF(IF(IF(ISERROR('Base vs Growth vs Downside key'!I14>0),'Base vs Growth vs Downside key'!I14>0,IF('Base vs Growth vs Downside key'!I14="","",'Base vs Growth vs Downside key'!I14>0))="",FALSE,IF(ISERROR('Base vs Growth vs Downside key'!I14>0),'Base vs Growth vs Downside key'!I14>0,IF('Base vs Growth vs Downside key'!I14="","",'Base vs Growth vs Downside key'!I14>0))),'Base vs Growth vs Downside key'!I17/'Base vs Growth vs Downside key'!I14,"") -> 4.3554916 | ... Y20: =IF(IF(IF(ISERROR('Base vs Growth vs Downside key'!Y14>0),'Base vs Growth vs Downside key'!Y14>0,IF('Base vs Growth vs Downside key'!Y14="","",'Base vs Growth vs Downside key'!Y14>0))="",FALSE,IF(ISERROR('Base vs Growth vs Downside key'!Y14>0),'Base vs Growth vs Downside key'!Y14>0,IF('Base vs Growth vs Downside key'!Y14="","",'Base vs Growth vs Downside key'!Y14>0))),'Base vs Growth vs Downside key'!Y17/'Base vs Growth vs Downside key'!Y14,"") -> -52.353706
A21: Months of runway > Growth | B21: =IF(IF(IF(ISERROR('Base vs Growth vs Downside key'!B15>0),'Base vs Growth vs Downside key'!B15>0,IF('Base vs Growth vs Downside key'!B15="","",'Base vs Growth vs Downside key'!B15>0))="",FALSE,IF(ISERROR('Base vs Growth vs Downside key'!B15>0),'Base vs Growth vs Downside key'!B15>0,IF('Base vs Growth vs Downside key'!B15="","",'Base vs Growth vs Downside key'!B15>0))),'Base vs Growth vs Downside key'!B18/'Base vs Growth vs Downside key'!B15,"") -> 10.819213 | C21: =IF(IF(IF(ISERROR('Base vs Growth vs Downside key'!C15>0),'Base vs Growth vs Downside key'!C15>0,IF('Base vs Growth vs Downside key'!C15="","",'Base vs Growth vs Downside key'!C15>0))="",FALSE,IF(ISERROR('Base vs Growth vs Downside key'!C15>0),'Base vs Growth vs Downside key'!C15>0,IF('Base vs Growth vs Downside key'!C15="","",'Base vs Growth vs Downside key'!C15>0))),'Base vs Growth vs Downside key'!C18/'Base vs Growth vs Downside key'!C15,"") -> 9.8192133 | D21: =IF(IF(IF(ISERROR('Base vs Growth vs Downside key'!D15>0),'Base vs Growth vs Downside key'!D15>0,IF('Base vs Growth vs Downside key'!D15="","",'Base vs Growth vs Downside key'!D15>0))="",FALSE,IF(ISERROR('Base vs Growth vs Downside key'!D15>0),'Base vs Growth vs Downside key'!D15>0,IF('Base vs Growth vs Downside key'!D15="","",'Base vs Growth vs Downside key'!D15>0))),'Base vs Growth vs Downside key'!D18/'Base vs Growth vs Downside key'!D15,"") -> 8.8192133 | E21: =IF(IF(IF(ISERROR('Base vs Growth vs Downside key'!E15>0),'Base vs Growth vs Downside key'!E15>0,IF('Base vs Growth vs Downside key'!E15="","",'Base vs Growth vs Downside key'!E15>0))="",FALSE,IF(ISERROR('Base vs Growth vs Downside key'!E15>0),'Base vs Growth vs Downside key'!E15>0,IF('Base vs Growth vs Downside key'!E15="","",'Base vs Growth vs Downside key'!E15>0))),'Base vs Growth vs Downside key'!E18/'Base vs Growth vs Downside key'!E15,"") -> 10.51006 | F21: =IF(IF(IF(ISERROR('Base vs Growth vs Downside key'!F15>0),'Base vs Growth vs Downside key'!F15>0,IF('Base vs Growth vs Downside key'!F15="","",'Base vs Growth vs Downside key'!F15>0))="",FALSE,IF(ISERROR('Base vs Growth vs Downside key'!F15>0),'Base vs Growth vs Downside key'!F15>0,IF('Base vs Growth vs Downside key'!F15="","",'Base vs Growth vs Downside key'!F15>0))),'Base vs Growth vs Downside key'!F18/'Base vs Growth vs Downside key'!F15,"") -> 11.851197 | G21: =IF(IF(IF(ISERROR('Base vs Growth vs Downside key'!G15>0),'Base vs Growth vs Downside key'!G15>0,IF('Base vs Growth vs Downside key'!G15="","",'Base vs Growth vs Downside key'!G15>0))="",FALSE,IF(ISERROR('Base vs Growth vs Downside key'!G15>0),'Base vs Growth vs Downside key'!G15>0,IF('Base vs Growth vs Downside key'!G15="","",'Base vs Growth vs Downside key'!G15>0))),'Base vs Growth vs Downside key'!G18/'Base vs Growth vs Downside key'!G15,"") -> 17.903726 | H21: =IF(IF(IF(ISERROR('Base vs Growth vs Downside key'!H15>0),'Base vs Growth vs Downside key'!H15>0,IF('Base vs Growth vs Downside key'!H15="","",'Base vs Growth vs Downside key'!H15>0))="",FALSE,IF(ISERROR('Base vs Growth vs Downside key'!H15>0),'Base vs Growth vs Downside key'!H15>0,IF('Base vs Growth vs Downside key'!H15="","",'Base vs Growth vs Downside key'!H15>0))),'Base vs Growth vs Downside key'!H18/'Base vs Growth vs Downside key'!H15,"") -> 55.642554 | I21: =IF(IF(IF(ISERROR('Base vs Growth vs Downside key'!I15>0),'Base vs Growth vs Downside key'!I15>0,IF('Base vs Growth vs Downside key'!I15="","",'Base vs Growth vs Downside key'!I15>0))="",FALSE,IF(ISERROR('Base vs Growth vs Downside key'!I15>0),'Base vs Growth vs Downside key'!I15>0,IF('Base vs Growth vs Downside key'!I15="","",'Base vs Growth vs Downside key'!I15>0))),'Base vs Growth vs Downside key'!I18/'Base vs Growth vs Downside key'!I15,"") | ... Y21: =IF(IF(IF(ISERROR('Base vs Growth vs Downside key'!Y15>0),'Base vs Growth vs Downside key'!Y15>0,IF('Base vs Growth vs Downside key'!Y15="","",'Base vs Growth vs Downside key'!Y15>0))="",FALSE,IF(ISERROR('Base vs Growth vs Downside key'!Y15>0),'Base vs Growth vs Downside key'!Y15>0,IF('Base vs Growth vs Downside key'!Y15="","",'Base vs Growth vs Downside key'!Y15>0))),'Base vs Growth vs Downside key'!Y18/'Base vs Growth vs Downside key'!Y15,"")
A22: Months of runway > delta | B22: ='Base vs Growth vs Downside key'!B21-'Base vs Growth vs Downside key'!B20 -> 0 | C22: ='Base vs Growth vs Downside key'!C21-'Base vs Growth vs Downside key'!C20 -> 0 | D22: ='Base vs Growth vs Downside key'!D21-'Base vs Growth vs Downside key'!D20 -> 0 | E22: ='Base vs Growth vs Downside key'!E21-'Base vs Growth vs Downside key'!E20 -> 2.6908465 | F22: ='Base vs Growth vs Downside key'!F21-'Base vs Growth vs Downside key'!F20 -> 5.0319836 | G22: ='Base vs Growth vs Downside key'!G21-'Base vs Growth vs Downside key'!G20 -> 12.084512 | H22: ='Base vs Growth vs Downside key'!H21-'Base vs Growth vs Downside key'!H20 -> 50.613793

Sheet Model inputs
A1: Model inputs
A2: Integration values are aggregated snapshots; raw source records are not included.
A4: Variables
A5: Variable / segment | B5: 2026-11 | C5: 2026-12 | D5: 2027-01 | E5: 2027-02 | F5: 2027-03 | G5: 2027-04 | H5: 2027-05 | I5: 2027-06 | J5: 2027-07 | K5: 2027-08 | L5: 2027-09 | M5: 2027-10 | N5: 2027-11 | O5: 2027-12 | P5: 2028-01 | Q5: 2028-02 | R5: 2028-03 | S5: 2028-04 | T5: 2028-05 | U5: 2028-06 | V5: 2028-07 | W5: 2028-08 | X5: 2028-09 | Y5: 2028-10 | Z5: 2026-09 | AA5: 2026-10 | AB5: Value
A6: Customers | B6: =SUM('Model inputs'!B7,'Model inputs'!B8) -> 0 | C6: =SUM('Model inputs'!C7,'Model inputs'!C8) -> 0 | D6: =SUM('Model inputs'!D7,'Model inputs'!D8) -> 0 | E6: =SUM('Model inputs'!E7,'Model inputs'!E8) -> 0 | F6: =SUM('Model inputs'!F7,'Model inputs'!F8) -> 0 | G6: =SUM('Model inputs'!G7,'Model inputs'!G8) -> 0 | H6: =SUM('Model inputs'!H7,'Model inputs'!H8) -> 2 | I6: =SUM('Model inputs'!I7,'Model inputs'!I8) -> 4 | ... Y6: =SUM('Model inputs'!Y7,'Model inputs'!Y8) -> 42
