Workbook

Sheet Monthly P&L, cash and runway
A1: Monthly P&L, cash and runway
A2: Monthly P&L & Cash · Main Scenario
A4: Variable / dimension | B4: 2026-11 | C4: 2026-12 | D4: 2027-01 | E4: 2027-02 | F4: 2027-03 | G4: 2027-04 | H4: 2027-05 | I4: 2027-06 | J4: 2027-07 | K4: 2027-08 | L4: 2027-09 | M4: 2027-10 | N4: 2027-11 | O4: 2027-12 | P4: 2028-01 | Q4: 2028-02 | R4: 2028-03 | S4: 2028-04 | T4: 2028-05 | U4: 2028-06 | V4: 2028-07 | W4: 2028-08 | X4: 2028-09 | Y4: 2028-10
A5: Model month | B5: =IFERROR(DATEDIF(DATE(2026,11,1),DATE(2026,11,1),"M")+1,0) -> 1 | C5: =IFERROR(DATEDIF(DATE(2026,11,1),DATE(2026,12,1),"M")+1,0) -> 2 | D5: =IFERROR(DATEDIF(DATE(2026,11,1),DATE(2027,1,1),"M")+1,0) -> 3 | E5: =IFERROR(DATEDIF(DATE(2026,11,1),DATE(2027,2,1),"M")+1,0) -> 4 | F5: =IFERROR(DATEDIF(DATE(2026,11,1),DATE(2027,3,1),"M")+1,0) -> 5 | G5: =IFERROR(DATEDIF(DATE(2026,11,1),DATE(2027,4,1),"M")+1,0) -> 6 | H5: =IFERROR(DATEDIF(DATE(2026,11,1),DATE(2027,5,1),"M")+1,0) -> 7 | I5: =IFERROR(DATEDIF(DATE(2026,11,1),DATE(2027,6,1),"M")+1,0) -> 8 | J5: =IFERROR(DATEDIF(DATE(2026,11,1),DATE(2027,7,1),"M")+1,0) -> 9 | K5: =IFERROR(DATEDIF(DATE(2026,11,1),DATE(2027,8,1),"M")+1,0) -> 10 | L5: =IFERROR(DATEDIF(DATE(2026,11,1),DATE(2027,9,1),"M")+1,0) -> 11 | M5: =IFERROR(DATEDIF(DATE(2026,11,1),DATE(2027,10,1),"M")+1,0) -> 12 | N5: =IFERROR(DATEDIF(DATE(2026,11,1),DATE(2027,11,1),"M")+1,0) -> 13 | O5: =IFERROR(DATEDIF(DATE(2026,11,1),DATE(2027,12,1),"M")+1,0) -> 14 | P5: =IFERROR(DATEDIF(DATE(2026,11,1),DATE(2028,1,1),"M")+1,0) -> 15 | Q5: =IFERROR(DATEDIF(DATE(2026,11,1),DATE(2028,2,1),"M")+1,0) -> 16 | R5: =IFERROR(DATEDIF(DATE(2026,11,1),DATE(2028,3,1),"M")+1,0) -> 17 | S5: =IFERROR(DATEDIF(DATE(2026,11,1),DATE(2028,4,1),"M")+1,0) -> 18 | T5: =IFERROR(DATEDIF(DATE(2026,11,1),DATE(2028,5,1),"M")+1,0) -> 19 | U5: =IFERROR(DATEDIF(DATE(2026,11,1),DATE(2028,6,1),"M")+1,0) -> 20 | V5: =IFERROR(DATEDIF(DATE(2026,11,1),DATE(2028,7,1),"M")+1,0) -> 21 | W5: =IFERROR(DATEDIF(DATE(2026,11,1),DATE(2028,8,1),"M")+1,0) -> 22 | X5: =IFERROR(DATEDIF(DATE(2026,11,1),DATE(2028,9,1),"M")+1,0) -> 23 | Y5: =IFERROR(DATEDIF(DATE(2026,11,1),DATE(2028,10,1),"M")+1,0) -> 24
A6: Customers | B6: =SUM('Monthly P&L, cash and runway'!B7,'Monthly P&L, cash and runway'!B8) -> 0 | C6: =SUM('Monthly P&L, cash and runway'!C7,'Monthly P&L, cash and runway'!C8) -> 0 | D6: =SUM('Monthly P&L, cash and runway'!D7,'Monthly P&L, cash and runway'!D8) -> 0 | E6: =SUM('Monthly P&L, cash and runway'!E7,'Monthly P&L, cash and runway'!E8) -> 2 | F6: =SUM('Monthly P&L, cash and runway'!F7,'Monthly P&L, cash and runway'!F8) -> 4 | G6: =SUM('Monthly P&L, cash and runway'!G7,'Monthly P&L, cash and runway'!G8) -> 6 | H6: =SUM('Monthly P&L, cash and runway'!H7,'Monthly P&L, cash and runway'!H8) -> 8 | I6: =SUM('Monthly P&L, cash and runway'!I7,'Monthly P&L, cash and runway'!I8) -> 10 | ... Y6: =SUM('Monthly P&L, cash and runway'!Y7,'Monthly P&L, cash and runway'!Y8) -> 50
A7: Starter | B7: =IF(IF(IF(ISERROR('Monthly P&L, cash and runway'!B5<1),'Monthly P&L, cash and runway'!B5<1,IF('Monthly P&L, cash and runway'!B5="","",'Monthly P&L, cash and runway'!B5<1))="",FALSE,IF(ISERROR('Monthly P&L, cash and runway'!B5<1),'Monthly P&L, cash and runway'!B5<1,IF('Monthly P&L, cash and runway'!B5="","",'Monthly P&L, cash and runway'!B5<1))),0,ROUND(IF(IF(IF(ISERROR('Monthly P&L, cash and runway'!B5<=3),'Monthly P&L, cash and runway'!B5<=3,IF('Monthly P&L, cash and runway'!B5="","",'Monthly P&L, cash and runway'!B5<=3))="",FALSE,IF(ISERROR('Monthly P&L, cash and runway'!B5<=3),'Monthly P&L, cash and runway'!B5<=3,IF('Monthly P&L, cash and runway'!B5="","",'Monthly P&L, cash and runway'!B5<=3))),IF('Model inputs'!B52="","",'Model inputs'!B52),IF(IF(IF(ISERROR('Monthly P&L, cash and runway'!B5<=6),'Monthly P&L, cash and runway'!B5<=6,IF('Monthly P&L, cash and runway'!B5="","",'Monthly P&L, cash and runway'!B5<=6))="",FALSE,IF(ISERROR('Monthly P&L, cash and runway'!B5<=6),'Monthly P&L, cash and runway'!B5<=6,IF('Monthly P&L, cash and runway'!B5="","",'Monthly P&L, cash and runway'!B5<=6))),'Model inputs'!B52+('Model inputs'!B55-'Model inputs'!B52)*('Monthly P&L, cash and runway'!B5-3)/3,IF(IF(IF(ISERROR('Monthly P&L, cash and runway'!B5<=12),'Monthly P&L, cash and runway'!B5<=12,IF('Monthly P&L, cash and runway'!B5="","",'Monthly P&L, cash and runway'!B5<=12))="",FALSE,IF(ISERROR('Monthly P&L, cash and runway'!B5<=12),'Monthly P&L, cash and runway'!B5<=12,IF('Monthly P&L, cash and runway'!B5="","",'Monthly P&L, cash and runway'!B5<=12))),'Model inputs'!B55+('Model inputs'!B46-'Model inputs'!B55)*('Monthly P&L, cash and runway'!B5-6)/6,'Model inputs'!B46+('Model inputs'!B49-'Model inputs'!B46)*('Monthly P&L, cash and runway'!B5-12)/12))),0)) -> 0 | C7: =IF(IF(IF(ISERROR('Monthly P&L, cash and runway'!C5<1),'Monthly P&L, cash and runway'!C5<1,IF('Monthly P&L, cash and runway'!C5="","",'Monthly P&L, cash and runway'!C5<1))="",FALSE,IF(ISERROR('Monthly P&L, cash and runway'!C5<1),'Monthly P&L, cash and runway'!C5<1,IF('Monthly P&L, cash and runway'!C5="","",'Monthly P&L, cash and runway'!C5<1))),0,ROUND(IF(IF(IF(ISERROR('Monthly P&L, cash and runway'!C5<=3),'Monthly P&L, cash and runway'!C5<=3,IF('Monthly P&L, cash and runway'!C5="","",'Monthly P&L, cash and runway'!C5<=3))="",FALSE,IF(ISERROR('Monthly P&L, cash and runway'!C5<=3),'Monthly P&L, cash and runway'!C5<=3,IF('Monthly P&L, cash and runway'!C5="","",'Monthly P&L, cash and runway'!C5<=3))),IF('Model inputs'!B52="","",'Model inputs'!B52),IF(IF(IF(ISERROR('Monthly P&L, cash and runway'!C5<=6),'Monthly P&L, cash and runway'!C5<=6,IF('Monthly P&L, cash and runway'!C5="","",'Monthly P&L, cash and runway'!C5<=6))="",FALSE,IF(ISERROR('Monthly P&L, cash and runway'!C5<=6),'Monthly P&L, cash and runway'!C5<=6,IF('Monthly P&L, cash and runway'!C5="","",'Monthly P&L, cash and runway'!C5<=6))),'Model inputs'!B52+('Model inputs'!B55-'Model inputs'!B52)*('Monthly P&L, cash and runway'!C5-3)/3,IF(IF(IF(ISERROR('Monthly P&L, cash and runway'!C5<=12),'Monthly P&L, cash and runway'!C5<=12,IF('Monthly P&L, cash and runway'!C5="","",'Monthly P&L, cash and runway'!C5<=12))="",FALSE,IF(ISERROR('Monthly P&L, cash and runway'!C5<=12),'Monthly P&L, cash and runway'!C5<=12,IF('Monthly P&L, cash and runway'!C5="","",'Monthly P&L, cash and runway'!C5<=12))),'Model inputs'!B55+('Model inputs'!B46-'Model inputs'!B55)*('Monthly P&L, cash and runway'!C5-6)/6,'Model inputs'!B46+('Model inputs'!B49-'Model inputs'!B46)*('Monthly P&L, cash and runway'!C5-12)/12))),0)) -> 0 | D7: =IF(IF(IF(ISERROR('Monthly P&L, cash and runway'!D5<1),'Monthly P&L, cash and runway'!D5<1,IF('Monthly P&L, cash and runway'!D5="","",'Monthly P&L, cash and runway'!D5<1))="",FALSE,IF(ISERROR('Monthly P&L, cash and runway'!D5<1),'Monthly P&L, cash and runway'!D5<1,IF('Monthly P&L, cash and runway'!D5="","",'Monthly P&L, cash and runway'!D5<1))),0,ROUND(IF(IF(IF(ISERROR('Monthly P&L, cash and runway'!D5<=3),'Monthly P&L, cash and runway'!D5<=3,IF('Monthly P&L, cash and runway'!D5="","",'Monthly P&L, cash and runway'!D5<=3))="",FALSE,IF(ISERROR('Monthly P&L, cash and runway'!D5<=3),'Monthly P&L, cash and runway'!D5<=3,IF('Monthly P&L, cash and runway'!D5="","",'Monthly P&L, cash and runway'!D5<=3))),IF('Model inputs'!B52="","",'Model inputs'!B52),IF(IF(IF(ISERROR('Monthly P&L, cash and runway'!D5<=6),'Monthly P&L, cash and runway'!D5<=6,IF('Monthly P&L, cash and runway'!D5="","",'Monthly P&L, cash and runway'!D5<=6))="",FALSE,IF(ISERROR('Monthly P&L, cash and runway'!D5<=6),'Monthly P&L, cash and runway'!D5<=6,IF('Monthly P&L, cash and runway'!D5="","",'Monthly P&L, cash and runway'!D5<=6))),'Model inputs'!B52+('Model inputs'!B55-'Model inputs'!B52)*('Monthly P&L, cash and runway'!D5-3)/3,IF(IF(IF(ISERROR('Monthly P&L, cash and runway'!D5<=12),'Monthly P&L, cash and runway'!D5<=12,IF('Monthly P&L, cash and runway'!D5="","",'Monthly P&L, cash and runway'!D5<=12))="",FALSE,IF(ISERROR('Monthly P&L, cash and runway'!D5<=12),'Monthly P&L, cash and runway'!D5<=12,IF('Monthly P&L, cash and runway'!D5="","",'Monthly P&L, cash and runway'!D5<=12))),'Model inputs'!B55+('Model inputs'!B46-'Model inputs'!B55)*('Monthly P&L, cash and runway'!D5-6)/6,'Model inputs'!B46+('Model inputs'!B49-'Model inputs'!B46)*('Monthly P&L, cash and runway'!D5-12)/12))),0)) -> 0 | E7: =IF(IF(IF(ISERROR('Monthly P&L, cash and runway'!E5<1),'Monthly P&L, cash and runway'!E5<1,IF('Monthly P&L, cash and runway'!E5="","",'Monthly P&L, cash and runway'!E5<1))="",FALSE,IF(ISERROR('Monthly P&L, cash and runway'!E5<1),'Monthly P&L, cash and runway'!E5<1,IF('Monthly P&L, cash and runway'!E5="","",'Monthly P&L, cash and runway'!E5<1))),0,ROUND(IF(IF(IF(ISERROR('Monthly P&L, cash and runway'!E5<=3),'Monthly P&L, cash and runway'!E5<=3,IF('Monthly P&L, cash and runway'!E5="","",'Monthly P&L, cash and runway'!E5<=3))="",FALSE,IF(ISERROR('Monthly P&L, cash and runway'!E5<=3),'Monthly P&L, cash and runway'!E5<=3,IF('Monthly P&L, cash and runway'!E5="","",'Monthly P&L, cash and runway'!E5<=3))),IF('Model inputs'!B52="","",'Model inputs'!B52),IF(IF(IF(ISERROR('Monthly P&L, cash and runway'!E5<=6),'Monthly P&L, cash and runway'!E5<=6,IF('Monthly P&L, cash and runway'!E5="","",'Monthly P&L, cash and runway'!E5<=6))="",FALSE,IF(ISERROR('Monthly P&L, cash and runway'!E5<=6),'Monthly P&L, cash and runway'!E5<=6,IF('Monthly P&L, cash and runway'!E5="","",'Monthly P&L, cash and runway'!E5<=6))),'Model inputs'!B52+('Model inputs'!B55-'Model inputs'!B52)*('Monthly P&L, cash and runway'!E5-3)/3,IF(IF(IF(ISERROR('Monthly P&L, cash and runway'!E5<=12),'Monthly P&L, cash and runway'!E5<=12,IF('Monthly P&L, cash and runway'!E5="","",'Monthly P&L, cash and runway'!E5<=12))="",FALSE,IF(ISERROR('Monthly P&L, cash and runway'!E5<=12),'Monthly P&L, cash and runway'!E5<=12,IF('Monthly P&L, cash and runway'!E5="","",'Monthly P&L, cash and runway'!E5<=12))),'Model inputs'!B55+('Model inputs'!B46-'Model inputs'!B55)*('Monthly P&L, cash and runway'!E5-6)/6,'Model inputs'!B46+('Model inputs'!B49-'Model inputs'!B46)*('Monthly P&L, cash and runway'!E5-12)/12))),0)) -> 2 | F7: =IF(IF(IF(ISERROR('Monthly P&L, cash and runway'!F5<1),'Monthly P&L, cash and runway'!F5<1,IF('Monthly P&L, cash and runway'!F5="","",'Monthly P&L, cash and runway'!F5<1))="",FALSE,IF(ISERROR('Monthly P&L, cash and runway'!F5<1),'Monthly P&L, cash and runway'!F5<1,IF('Monthly P&L, cash and runway'!F5="","",'Monthly P&L, cash and runway'!F5<1))),0,ROUND(IF(IF(IF(ISERROR('Monthly P&L, cash and runway'!F5<=3),'Monthly P&L, cash and runway'!F5<=3,IF('Monthly P&L, cash and runway'!F5="","",'Monthly P&L, cash and runway'!F5<=3))="",FALSE,IF(ISERROR('Monthly P&L, cash and runway'!F5<=3),'Monthly P&L, cash and runway'!F5<=3,IF('Monthly P&L, cash and runway'!F5="","",'Monthly P&L, cash and runway'!F5<=3))),IF('Model inputs'!B52="","",'Model inputs'!B52),IF(IF(IF(ISERROR('Monthly P&L, cash and runway'!F5<=6),'Monthly P&L, cash and runway'!F5<=6,IF('Monthly P&L, cash and runway'!F5="","",'Monthly P&L, cash and runway'!F5<=6))="",FALSE,IF(ISERROR('Monthly P&L, cash and runway'!F5<=6),'Monthly P&L, cash and runway'!F5<=6,IF('Monthly P&L, cash and runway'!F5="","",'Monthly P&L, cash and runway'!F5<=6))),'Model inputs'!B52+('Model inputs'!B55-'Model inputs'!B52)*('Monthly P&L, cash and runway'!F5-3)/3,IF(IF(IF(ISERROR('Monthly P&L, cash and runway'!F5<=12),'Monthly P&L, cash and runway'!F5<=12,IF('Monthly P&L, cash and runway'!F5="","",'Monthly P&L, cash and runway'!F5<=12))="",FALSE,IF(ISERROR('Monthly P&L, cash and runway'!F5<=12),'Monthly P&L, cash and runway'!F5<=12,IF('Monthly P&L, cash and runway'!F5="","",'Monthly P&L, cash and runway'!F5<=12))),'Model inputs'!B55+('Model inputs'!B46-'Model inputs'!B55)*('Monthly P&L, cash and runway'!F5-6)/6,'Model inputs'!B46+('Model inputs'!B49-'Model inputs'!B46)*('Monthly P&L, cash and runway'!F5-12)/12))),0)) -> 3 | G7: =IF(IF(IF(ISERROR('Monthly P&L, cash and runway'!G5<1),'Monthly P&L, cash and runway'!G5<1,IF('Monthly P&L, cash and runway'!G5="","",'Monthly P&L, cash and runway'!G5<1))="",FALSE,IF(ISERROR('Monthly P&L, cash and runway'!G5<1),'Monthly P&L, cash and runway'!G5<1,IF('Monthly P&L, cash and runway'!G5="","",'Monthly P&L, cash and runway'!G5<1))),0,ROUND(IF(IF(IF(ISERROR('Monthly P&L, cash and runway'!G5<=3),'Monthly P&L, cash and runway'!G5<=3,IF('Monthly P&L, cash and runway'!G5="","",'Monthly P&L, cash and runway'!G5<=3))="",FALSE,IF(ISERROR('Monthly P&L, cash and runway'!G5<=3),'Monthly P&L, cash and runway'!G5<=3,IF('Monthly P&L, cash and runway'!G5="","",'Monthly P&L, cash and runway'!G5<=3))),IF('Model inputs'!B52="","",'Model inputs'!B52),IF(IF(IF(ISERROR('Monthly P&L, cash and runway'!G5<=6),'Monthly P&L, cash and runway'!G5<=6,IF('Monthly P&L, cash and runway'!G5="","",'Monthly P&L, cash and runway'!G5<=6))="",FALSE,IF(ISERROR('Monthly P&L, cash and runway'!G5<=6),'Monthly P&L, cash and runway'!G5<=6,IF('Monthly P&L, cash and runway'!G5="","",'Monthly P&L, cash and runway'!G5<=6))),'Model inputs'!B52+('Model inputs'!B55-'Model inputs'!B52)*('Monthly P&L, cash and runway'!G5-3)/3,IF(IF(IF(ISERROR('Monthly P&L, cash and runway'!G5<=12),'Monthly P&L, cash and runway'!G5<=12,IF('Monthly P&L, cash and runway'!G5="","",'Monthly P&L, cash and runway'!G5<=12))="",FALSE,IF(ISERROR('Monthly P&L, cash and runway'!G5<=12),'Monthly P&L, cash and runway'!G5<=12,IF('Monthly P&L, cash and runway'!G5="","",'Monthly P&L, cash and runway'!G5<=12))),'Model inputs'!B55+('Model inputs'!B46-'Model inputs'!B55)*('Monthly P&L, cash and runway'!G5-6)/6,'Model inputs'!B46+('Model inputs'!B49-'Model inputs'!B46)*('Monthly P&L, cash and runway'!G5-12)/12))),0)) -> 5 | H7: =IF(IF(IF(ISERROR('Monthly P&L, cash and runway'!H5<1),'Monthly P&L, cash and runway'!H5<1,IF('Monthly P&L, cash and runway'!H5="","",'Monthly P&L, cash and runway'!H5<1))="",FALSE,IF(ISERROR('Monthly P&L, cash and runway'!H5<1),'Monthly P&L, cash and runway'!H5<1,IF('Monthly P&L, cash and runway'!H5="","",'Monthly P&L, cash and runway'!H5<1))),0,ROUND(IF(IF(IF(ISERROR('Monthly P&L, cash and runway'!H5<=3),'Monthly P&L, cash and runway'!H5<=3,IF('Monthly P&L, cash and runway'!H5="","",'Monthly P&L, cash and runway'!H5<=3))="",FALSE,IF(ISERROR('Monthly P&L, cash and runway'!H5<=3),'Monthly P&L, cash and runway'!H5<=3,IF('Monthly P&L, cash and runway'!H5="","",'Monthly P&L, cash and runway'!H5<=3))),IF('Model inputs'!B52="","",'Model inputs'!B52),IF(IF(IF(ISERROR('Monthly P&L, cash and runway'!H5<=6),'Monthly P&L, cash and runway'!H5<=6,IF('Monthly P&L, cash and runway'!H5="","",'Monthly P&L, cash and runway'!H5<=6))="",FALSE,IF(ISERROR('Monthly P&L, cash and runway'!H5<=6),'Monthly P&L, cash and runway'!H5<=6,IF('Monthly P&L, cash and runway'!H5="","",'Monthly P&L, cash and runway'!H5<=6))),'Model inputs'!B52+('Model inputs'!B55-'Model inputs'!B52)*('Monthly P&L, cash and runway'!H5-3)/3,IF(IF(IF(ISERROR('Monthly P&L, cash and runway'!H5<=12),'Monthly P&L, cash and runway'!H5<=12,IF('Monthly P&L, cash and runway'!H5="","",'Monthly P&L, cash and runway'!H5<=12))="",FALSE,IF(ISERROR('Monthly P&L, cash and runway'!H5<=12),'Monthly P&L, cash and runway'!H5<=12,IF('Monthly P&L, cash and runway'!H5="","",'Monthly P&L, cash and runway'!H5<=12))),'Model inputs'!B55+('Model inputs'!B46-'Model inputs'!B55)*('Monthly P&L, cash and runway'!H5-6)/6,'Model inputs'!B46+('Model inputs'!B49-'Model inputs'!B46)*('Monthly P&L, cash and runway'!H5-12)/12))),0)) -> 7 | I7: =IF(IF(IF(ISERROR('Monthly P&L, cash and runway'!I5<1),'Monthly P&L, cash and runway'!I5<1,IF('Monthly P&L, cash and runway'!I5="","",'Monthly P&L, cash and runway'!I5<1))="",FALSE,IF(ISERROR('Monthly P&L, cash and runway'!I5<1),'Monthly P&L, cash and runway'!I5<1,IF('Monthly P&L, cash and runway'!I5="","",'Monthly P&L, cash and runway'!I5<1))),0,ROUND(IF(IF(IF(ISERROR('Monthly P&L, cash and runway'!I5<=3),'Monthly P&L, cash and runway'!I5<=3,IF('Monthly P&L, cash and runway'!I5="","",'Monthly P&L, cash and runway'!I5<=3))="",FALSE,IF(ISERROR('Monthly P&L, cash and runway'!I5<=3),'Monthly P&L, cash and runway'!I5<=3,IF('Monthly P&L, cash and runway'!I5="","",'Monthly P&L, cash and runway'!I5<=3))),IF('Model inputs'!B52="","",'Model inputs'!B52),IF(IF(IF(ISERROR('Monthly P&L, cash and runway'!I5<=6),'Monthly P&L, cash and runway'!I5<=6,IF('Monthly P&L, cash and runway'!I5="","",'Monthly P&L, cash and runway'!I5<=6))="",FALSE,IF(ISERROR('Monthly P&L, cash and runway'!I5<=6),'Monthly P&L, cash and runway'!I5<=6,IF('Monthly P&L, cash and runway'!I5="","",'Monthly P&L, cash and runway'!I5<=6))),'Model inputs'!B52+('Model inputs'!B55-'Model inputs'!B52)*('Monthly P&L, cash and runway'!I5-3)/3,IF(IF(IF(ISERROR('Monthly P&L, cash and runway'!I5<=12),'Monthly P&L, cash and runway'!I5<=12,IF('Monthly P&L, cash and runway'!I5="","",'Monthly P&L, cash and runway'!I5<=12))="",FALSE,IF(ISERROR('Monthly P&L, cash and runway'!I5<=12),'Monthly P&L, cash and runway'!I5<=12,IF('Monthly P&L, cash and runway'!I5="","",'Monthly P&L, cash and runway'!I5<=12))),'Model inputs'!B55+('Model inputs'!B46-'Model inputs'!B55)*('Monthly P&L, cash and runway'!I5-6)/6,'Model inputs'!B46+('Model inputs'!B49-'Model inputs'!B46)*('Monthly P&L, cash and runway'!I5-12)/12))),0)) -> 8 | J7: =IF(IF(IF(ISERROR('Monthly P&L, cash and runway'!J5<1),'Monthly P&L, cash and runway'!J5<1,IF('Monthly P&L, cash and runway'!J5="","",'Monthly P&L, cash and runway'!J5<1))="",FALSE,IF(ISERROR('Monthly P&L, cash and runway'!J5<1),'Monthly P&L, cash and runway'!J5<1,IF('Monthly P&L, cash and runway'!J5="","",'Monthly P&L, cash and runway'!J5<1))),0,ROUND(IF(IF(IF(ISERROR('Monthly P&L, cash and runway'!J5<=3),'Monthly P&L, cash and runway'!J5<=3,IF('Monthly P&L, cash and runway'!J5="","",'Monthly P&L, cash and runway'!J5<=3))="",FALSE,IF(ISERROR('Monthly P&L, cash and runway'!J5<=3),'Monthly P&L, cash and runway'!J5<=3,IF('Monthly P&L, cash and runway'!J5="","",'Monthly P&L, cash and runway'!J5<=3))),IF('Model inputs'!B52="","",'Model inputs'!B52),IF(IF(IF(ISERROR('Monthly P&L, cash and runway'!J5<=6),'Monthly P&L, cash and runway'!J5<=6,IF('Monthly P&L, cash and runway'!J5="","",'Monthly P&L, cash and runway'!J5<=6))="",FALSE,IF(ISERROR('Monthly P&L, cash and runway'!J5<=6),'Monthly P&L, cash and runway'!J5<=6,IF('Monthly P&L, cash and runway'!J5="","",'Monthly P&L, cash and runway'!J5<=6))),'Model inputs'!B52+('Model inputs'!B55-'Model inputs'!B52)*('Monthly P&L, cash and runway'!J5-3)/3,IF(IF(IF(ISERROR('Monthly P&L, cash and runway'!J5<=12),'Monthly P&L, cash and runway'!J5<=12,IF('Monthly P&L, cash and runway'!J5="","",'Monthly P&L, cash and runway'!J5<=12))="",FALSE,IF(ISERROR('Monthly P&L, cash and runway'!J5<=12),'Monthly P&L, cash and runway'!J5<=12,IF('Monthly P&L, cash and runway'!J5="","",'Monthly P&L, cash and runway'!J5<=12))),'Model inputs'!B55+('Model inputs'!B46-'Model inputs'!B55)*('Monthly P&L, cash and runway'!J5-6)/6,'Model inputs'!B46+('Model inputs'!B49-'Model inputs'!B46)*('Monthly P&L, cash and runway'!J5-12)/12))),0)) -> 10 | K7: =IF(IF(IF(ISERROR('Monthly P&L, cash and runway'!K5<1),'Monthly P&L, cash and runway'!K5<1,IF('Monthly P&L, cash and runway'!K5="","",'Monthly P&L, cash and runway'!K5<1))="",FALSE,IF(ISERROR('Monthly P&L, cash and runway'!K5<1),'Monthly P&L, cash and runway'!K5<1,IF('Monthly P&L, cash and runway'!K5="","",'Monthly P&L, cash and runway'!K5<1))),0,ROUND(IF(IF(IF(ISERROR('Monthly P&L, cash and runway'!K5<=3),'Monthly P&L, cash and runway'!K5<=3,IF('Monthly P&L, cash and runway'!K5="","",'Monthly P&L, cash and runway'!K5<=3))="",FALSE,IF(ISERROR('Monthly P&L, cash and runway'!K5<=3),'Monthly P&L, cash and runway'!K5<=3,IF('Monthly P&L, cash and runway'!K5="","",'Monthly P&L, cash and runway'!K5<=3))),IF('Model inputs'!B52="","",'Model inputs'!B52),IF(IF(IF(ISERROR('Monthly P&L, cash and runway'!K5<=6),'Monthly P&L, cash and runway'!K5<=6,IF('Monthly P&L, cash and runway'!K5="","",'Monthly P&L, cash and runway'!K5<=6))="",FALSE,IF(ISERROR('Monthly P&L, cash and runway'!K5<=6),'Monthly P&L, cash and runway'!K5<=6,IF('Monthly P&L, cash and runway'!K5="","",'Monthly P&L, cash and runway'!K5<=6))),'Model inputs'!B52+('Model inputs'!B55-'Model inputs'!B52)*('Monthly P&L, cash and runway'!K5-3)/3,IF(IF(IF(ISERROR('Monthly P&L, cash and runway'!K5<=12),'Monthly P&L, cash and runway'!K5<=12,IF('Monthly P&L, cash and runway'!K5="","",'Monthly P&L, cash and runway'!K5<=12))="",FALSE,IF(ISERROR('Monthly P&L, cash and runway'!K5<=12),'Monthly P&L, cash and runway'!K5<=12,IF('Monthly P&L, cash and runway'!K5="","",'Monthly P&L, cash and runway'!K5<=12))),'Model inputs'!B55+('Model inputs'!B46-'Model inputs'!B55)*('Monthly P&L, cash and runway'!K5-6)/6,'Model inputs'!B46+('Model inputs'!B49-'Model inputs'!B46)*('Monthly P&L, cash and runway'!K5-12)/12))),0)) -> 12 | L7: =IF(IF(IF(ISERROR('Monthly P&L, cash and runway'!L5<1),'Monthly P&L, cash and runway'!L5<1,IF('Monthly P&L, cash and runway'!L5="","",'Monthly P&L, cash and runway'!L5<1))="",FALSE,IF(ISERROR('Monthly P&L, cash and runway'!L5<1),'Monthly P&L, cash and runway'!L5<1,IF('Monthly P&L, cash and runway'!L5="","",'Monthly P&L, cash and runway'!L5<1))),0,ROUND(IF(IF(IF(ISERROR('Monthly P&L, cash and runway'!L5<=3),'Monthly P&L, cash and runway'!L5<=3,IF('Monthly P&L, cash and runway'!L5="","",'Monthly P&L, cash and runway'!L5<=3))="",FALSE,IF(ISERROR('Monthly P&L, cash and runway'!L5<=3),'Monthly P&L, cash and runway'!L5<=3,IF('Monthly P&L, cash and runway'!L5="","",'Monthly P&L, cash and runway'!L5<=3))),IF('Model inputs'!B52="","",'Model inputs'!B52),IF(IF(IF(ISERROR('Monthly P&L, cash and runway'!L5<=6),'Monthly P&L, cash and runway'!L5<=6,IF('Monthly P&L, cash and runway'!L5="","",'Monthly P&L, cash and runway'!L5<=6))="",FALSE,IF(ISERROR('Monthly P&L, cash and runway'!L5<=6),'Monthly P&L, cash and runway'!L5<=6,IF('Monthly P&L, cash and runway'!L5="","",'Monthly P&L, cash and runway'!L5<=6))),'Model inputs'!B52+('Model inputs'!B55-'Model inputs'!B52)*('Monthly P&L, cash and runway'!L5-3)/3,IF(IF(IF(ISERROR('Monthly P&L, cash and runway'!L5<=12),'Monthly P&L, cash and runway'!L5<=12,IF('Monthly P&L, cash and runway'!L5="","",'Monthly P&L, cash and runway'!L5<=12))="",FALSE,IF(ISERROR('Monthly P&L, cash and runway'!L5<=12),'Monthly P&L, cash and runway'!L5<=12,IF('Monthly P&L, cash and runway'!L5="","",'Monthly P&L, cash and runway'!L5<=12))),'Model inputs'!B55+('Model inputs'!B46-'Model inputs'!B55)*('Monthly P&L, cash and runway'!L5-6)/6,'Model inputs'!B46+('Model inputs'!B49-'Model inputs'!B46)*('Monthly P&L, cash and runway'!L5-12)/12))),0)) -> 13 | M7: =IF(IF(IF(ISERROR('Monthly P&L, cash and runway'!M5<1),'Monthly P&L, cash and runway'!M5<1,IF('Monthly P&L, cash and runway'!M5="","",'Monthly P&L, cash and runway'!M5<1))="",FALSE,IF(ISERROR('Monthly P&L, cash and runway'!M5<1),'Monthly P&L, cash and runway'!M5<1,IF('Monthly P&L, cash and runway'!M5="","",'Monthly P&L, cash and runway'!M5<1))),0,ROUND(IF(IF(IF(ISERROR('Monthly P&L, cash and runway'!M5<=3),'Monthly P&L, cash and runway'!M5<=3,IF('Monthly P&L, cash and runway'!M5="","",'Monthly P&L, cash and runway'!M5<=3))="",FALSE,IF(ISERROR('Monthly P&L, cash and runway'!M5<=3),'Monthly P&L, cash and runway'!M5<=3,IF('Monthly P&L, cash and runway'!M5="","",'Monthly P&L, cash and runway'!M5<=3))),IF('Model inputs'!B52="","",'Model inputs'!B52),IF(IF(IF(ISERROR('Monthly P&L, cash and runway'!M5<=6),'Monthly P&L, cash and runway'!M5<=6,IF('Monthly P&L, cash and runway'!M5="","",'Monthly P&L, cash and runway'!M5<=6))="",FALSE,IF(ISERROR('Monthly P&L, cash and runway'!M5<=6),'Monthly P&L, cash and runway'!M5<=6,IF('Monthly P&L, cash and runway'!M5="","",'Monthly P&L, cash and runway'!M5<=6))),'Model inputs'!B52+('Model inputs'!B55-'Model inputs'!B52)*('Monthly P&L, cash and runway'!M5-3)/3,IF(IF(IF(ISERROR('Monthly P&L, cash and runway'!M5<=12),'Monthly P&L, cash and runway'!M5<=12,IF('Monthly P&L, cash and runway'!M5="","",'Monthly P&L, cash and runway'!M5<=12))="",FALSE,IF(ISERROR('Monthly P&L, cash and runway'!M5<=12),'Monthly P&L, cash and runway'!M5<=12,IF('Monthly P&L, cash and runway'!M5="","",'Monthly P&L, cash and runway'!M5<=12))),'Model inputs'!B55+('Model inputs'!B46-'Model inputs'!B55)*('Monthly P&L, cash and runway'!M5-6)/6,'Model inputs'!B46+('Model inputs'!B49-'Model inputs'!B46)*('Monthly P&L, cash and runway'!M5-12)/12))),0)) -> 15 | N7: =IF(IF(IF(ISERROR('Monthly P&L, cash and runway'!N5<1),'Monthly P&L, cash and runway'!N5<1,IF('Monthly P&L, cash and runway'!N5="","",'Monthly P&L, cash and runway'!N5<1))="",FALSE,IF(ISERROR('Monthly P&L, cash and runway'!N5<1),'Monthly P&L, cash and runway'!N5<1,IF('Monthly P&L, cash and runway'!N5="","",'Monthly P&L, cash and runway'!N5<1))),0,ROUND(IF(IF(IF(ISERROR('Monthly P&L, cash and runway'!N5<=3),'Monthly P&L, cash and runway'!N5<=3,IF('Monthly P&L, cash and runway'!N5="","",'Monthly P&L, cash and runway'!N5<=3))="",FALSE,IF(ISERROR('Monthly P&L, cash and runway'!N5<=3),'Monthly P&L, cash and runway'!N5<=3,IF('Monthly P&L, cash and runway'!N5="","",'Monthly P&L, cash and runway'!N5<=3))),IF('Model inputs'!B52="","",'Model inputs'!B52),IF(IF(IF(ISERROR('Monthly P&L, cash and runway'!N5<=6),'Monthly P&L, cash and runway'!N5<=6,IF('Monthly P&L, cash and runway'!N5="","",'Monthly P&L, cash and runway'!N5<=6))="",FALSE,IF(ISERROR('Monthly P&L, cash and runway'!N5<=6),'Monthly P&L, cash and runway'!N5<=6,IF('Monthly P&L, cash and runway'!N5="","",'Monthly P&L, cash and runway'!N5<=6))),'Model inputs'!B52+('Model inputs'!B55-'Model inputs'!B52)*('Monthly P&L, cash and runway'!N5-3)/3,IF(IF(IF(ISERROR('Monthly P&L, cash and runway'!N5<=12),'Monthly P&L, cash and runway'!N5<=12,IF('Monthly P&L, cash and runway'!N5="","",'Monthly P&L, cash and runway'!N5<=12))="",FALSE,IF(ISERROR('Monthly P&L, cash and runway'!N5<=12),'Monthly P&L, cash and runway'!N5<=12,IF('Monthly P&L, cash and runway'!N5="","",'Monthly P&L, cash and runway'!N5<=12))),'Model inputs'!B55+('Model inputs'!B46-'Model inputs'!B55)*('Monthly P&L, cash and runway'!N5-6)/6,'Model inputs'!B46+('Model inputs'!B49-'Model inputs'!B46)*('Monthly P&L, cash and runway'!N5-12)/12))),0)) -> 17 | O7: =IF(IF(IF(ISERROR('Monthly P&L, cash and runway'!O5<1),'Monthly P&L, cash and runway'!O5<1,IF('Monthly P&L, cash and runway'!O5="","",'Monthly P&L, cash and runway'!O5<1))="",FALSE,IF(ISERROR('Monthly P&L, cash and runway'!O5<1),'Monthly P&L, cash and runway'!O5<1,IF('Monthly P&L, cash and runway'!O5="","",'Monthly P&L, cash and runway'!O5<1))),0,ROUND(IF(IF(IF(ISERROR('Monthly P&L, cash and runway'!O5<=3),'Monthly P&L, cash and runway'!O5<=3,IF('Monthly P&L, cash and runway'!O5="","",'Monthly P&L, cash and runway'!O5<=3))="",FALSE,IF(ISERROR('Monthly P&L, cash and runway'!O5<=3),'Monthly P&L, cash and runway'!O5<=3,IF('Monthly P&L, cash and runway'!O5="","",'Monthly P&L, cash and runway'!O5<=3))),IF('Model inputs'!B52="","",'Model inputs'!B52),IF(IF(IF(ISERROR('Monthly P&L, cash and runway'!O5<=6),'Monthly P&L, cash and runway'!O5<=6,IF('Monthly P&L, cash and runway'!O5="","",'Monthly P&L, cash and runway'!O5<=6))="",FALSE,IF(ISERROR('Monthly P&L, cash and runway'!O5<=6),'Monthly P&L, cash and runway'!O5<=6,IF('Monthly P&L, cash and runway'!O5="","",'Monthly P&L, cash and runway'!O5<=6))),'Model inputs'!B52+('Model inputs'!B55-'Model inputs'!B52)*('Monthly P&L, cash and runway'!O5-3)/3,IF(IF(IF(ISERROR('Monthly P&L, cash and runway'!O5<=12),'Monthly P&L, cash and runway'!O5<=12,IF('Monthly P&L, cash and runway'!O5="","",'Monthly P&L, cash and runway'!O5<=12))="",FALSE,IF(ISERROR('Monthly P&L, cash and runway'!O5<=12),'Monthly P&L, cash and runway'!O5<=12,IF('Monthly P&L, cash and runway'!O5="","",'Monthly P&L, cash and runway'!O5<=12))),'Model inputs'!B55+('Model inputs'!B46-'Model inputs'!B55)*('Monthly P&L, cash and runway'!O5-6)/6,'Model inputs'!B46+('Model inputs'!B49-'Model inputs'!B46)*('Monthly P&L, cash and runway'!O5-12)/12))),0)) -> 19 | P7: =IF(IF(IF(ISERROR('Monthly P&L, cash and runway'!P5<1),'Monthly P&L, cash and runway'!P5<1,IF('Monthly P&L, cash and runway'!P5="","",'Monthly P&L, cash and runway'!P5<1))="",FALSE,IF(ISERROR('Monthly P&L, cash and runway'!P5<1),'Monthly P&L, cash and runway'!P5<1,IF('Monthly P&L, cash and runway'!P5="","",'Monthly P&L, cash and runway'!P5<1))),0,ROUND(IF(IF(IF(ISERROR('Monthly P&L, cash and runway'!P5<=3),'Monthly P&L, cash and runway'!P5<=3,IF('Monthly P&L, cash and runway'!P5="","",'Monthly P&L, cash and runway'!P5<=3))="",FALSE,IF(ISERROR('Monthly P&L, cash and runway'!P5<=3),'Monthly P&L, cash and runway'!P5<=3,IF('Monthly P&L, cash and runway'!P5="","",'Monthly P&L, cash and runway'!P5<=3))),IF('Model inputs'!B52="","",'Model inputs'!B52),IF(IF(IF(ISERROR('Monthly P&L, cash and runway'!P5<=6),'Monthly P&L, cash and runway'!P5<=6,IF('Monthly P&L, cash and runway'!P5="","",'Monthly P&L, cash and runway'!P5<=6))="",FALSE,IF(ISERROR('Monthly P&L, cash and runway'!P5<=6),'Monthly P&L, cash and runway'!P5<=6,IF('Monthly P&L, cash and runway'!P5="","",'Monthly P&L, cash and runway'!P5<=6))),'Model inputs'!B52+('Model inputs'!B55-'Model inputs'!B52)*('Monthly P&L, cash and runway'!P5-3)/3,IF(IF(IF(ISERROR('Monthly P&L, cash and runway'!P5<=12),'Monthly P&L, cash and runway'!P5<=12,IF('Monthly P&L, cash and runway'!P5="","",'Monthly P&L, cash and runway'!P5<=12))="",FALSE,IF(ISERROR('Monthly P&L, cash and runway'!P5<=12),'Monthly P&L, cash and runway'!P5<=12,IF('Monthly P&L, cash and runway'!P5="","",'Monthly P&L, cash and runway'!P5<=12))),'Model inputs'!B55+('Model inputs'!B46-'Model inputs'!B55)*('Monthly P&L, cash and runway'!P5-6)/6,'Model inputs'!B46+('Model inputs'!B49-'Model inputs'!B46)*('Monthly P&L, cash and runway'!P5-12)/12))),0)) -> 21 | Q7: =IF(IF(IF(ISERROR('Monthly P&L, cash and runway'!Q5<1),'Monthly P&L, cash and runway'!Q5<1,IF('Monthly P&L, cash and runway'!Q5="","",'Monthly P&L, cash and runway'!Q5<1))="",FALSE,IF(ISERROR('Monthly P&L, cash and runway'!Q5<1),'Monthly P&L, cash and runway'!Q5<1,IF('Monthly P&L, cash and runway'!Q5="","",'Monthly P&L, cash and runway'!Q5<1))),0,ROUND(IF(IF(IF(ISERROR('Monthly P&L, cash and runway'!Q5<=3),'Monthly P&L, cash and runway'!Q5<=3,IF('Monthly P&L, cash and runway'!Q5="","",'Monthly P&L, cash and runway'!Q5<=3))="",FALSE,IF(ISERROR('Monthly P&L, cash and runway'!Q5<=3),'Monthly P&L, cash and runway'!Q5<=3,IF('Monthly P&L, cash and runway'!Q5="","",'Monthly P&L, cash and runway'!Q5<=3))),IF('Model inputs'!B52="","",'Model inputs'!B52),IF(IF(IF(ISERROR('Monthly P&L, cash and runway'!Q5<=6),'Monthly P&L, cash and runway'!Q5<=6,IF('Monthly P&L, cash and runway'!Q5="","",'Monthly P&L, cash and runway'!Q5<=6))="",FALSE,IF(ISERROR('Monthly P&L, cash and runway'!Q5<=6),'Monthly P&L, cash and runway'!Q5<=6,IF('Monthly P&L, cash and runway'!Q5="","",'Monthly P&L, cash and runway'!Q5<=6))),'Model inputs'!B52+('Model inputs'!B55-'Model inputs'!B52)*('Monthly P&L, cash and runway'!Q5-3)/3,IF(IF(IF(ISERROR('Monthly P&L, cash and runway'!Q5<=12),'Monthly P&L, cash and runway'!Q5<=12,IF('Monthly P&L, cash and runway'!Q5="","",'Monthly P&L, cash and runway'!Q5<=12))="",FALSE,IF(ISERROR('Monthly P&L, cash and runway'!Q5<=12),'Monthly P&L, cash and runway'!Q5<=12,IF('Monthly P&L, cash and runway'!Q5="","",'Monthly P&L, cash and runway'!Q5<=12))),'Model inputs'!B55+('Model inputs'!B46-'Model inputs'!B55)*('Monthly P&L, cash and runway'!Q5-6)/6,'Model inputs'!B46+('Model inputs'!B49-'Model inputs'!B46)*('Monthly P&L, cash and runway'!Q5-12)/12))),0)) -> 23 | R7: =IF(IF(IF(ISERROR('Monthly P&L, cash and runway'!R5<1),'Monthly P&L, cash and runway'!R5<1,IF('Monthly P&L, cash and runway'!R5="","",'Monthly P&L, cash and runway'!R5<1))="",FALSE,IF(ISERROR('Monthly P&L, cash and runway'!R5<1),'Monthly P&L, cash and runway'!R5<1,IF('Monthly P&L, cash and runway'!R5="","",'Monthly P&L, cash and runway'!R5<1))),0,ROUND(IF(IF(IF(ISERROR('Monthly P&L, cash and runway'!R5<=3),'Monthly P&L, cash and runway'!R5<=3,IF('Monthly P&L, cash and runway'!R5="","",'Monthly P&L, cash and runway'!R5<=3))="",FALSE,IF(ISERROR('Monthly P&L, cash and runway'!R5<=3),'Monthly P&L, cash and runway'!R5<=3,IF('Monthly P&L, cash and runway'!R5="","",'Monthly P&L, cash and runway'!R5<=3))),IF('Model inputs'!B52="","",'Model inputs'!B52),IF(IF(IF(ISERROR('Monthly P&L, cash and runway'!R5<=6),'Monthly P&L, cash and runway'!R5<=6,IF('Monthly P&L, cash and runway'!R5="","",'Monthly P&L, cash and runway'!R5<=6))="",FALSE,IF(ISERROR('Monthly P&L, cash and runway'!R5<=6),'Monthly P&L, cash and runway'!R5<=6,IF('Monthly P&L, cash and runway'!R5="","",'Monthly P&L, cash and runway'!R5<=6))),'Model inputs'!B52+('Model inputs'!B55-'Model inputs'!B52)*('Monthly P&L, cash and runway'!R5-3)/3,IF(IF(IF(ISERROR('Monthly P&L, cash and runway'!R5<=12),'Monthly P&L, cash and runway'!R5<=12,IF('Monthly P&L, cash and runway'!R5="","",'Monthly P&L, cash and runway'!R5<=12))="",FALSE,IF(ISERROR('Monthly P&L, cash and runway'!R5<=12),'Monthly P&L, cash and runway'!R5<=12,IF('Monthly P&L, cash and runway'!R5="","",'Monthly P&L, cash and runway'!R5<=12))),'Model inputs'!B55+('Model inputs'!B46-'Model inputs'!B55)*('Monthly P&L, cash and runway'!R5-6)/6,'Model inputs'!B46+('Model inputs'!B49-'Model inputs'!B46)*('Monthly P&L, cash and runway'!R5-12)/12))),0)) -> 25 | S7: =IF(IF(IF(ISERROR('Monthly P&L, cash and runway'!S5<1),'Monthly P&L, cash and runway'!S5<1,IF('Monthly P&L, cash and runway'!S5="","",'Monthly P&L, cash and runway'!S5<1))="",FALSE,IF(ISERROR('Monthly P&L, cash and runway'!S5<1),'Monthly P&L, cash and runway'!S5<1,IF('Monthly P&L, cash and runway'!S5="","",'Monthly P&L, cash and runway'!S5<1))),0,ROUND(IF(IF(IF(ISERROR('Monthly P&L, cash and runway'!S5<=3),'Monthly P&L, cash and runway'!S5<=3,IF('Monthly P&L, cash and runway'!S5="","",'Monthly P&L, cash and runway'!S5<=3))="",FALSE,IF(ISERROR('Monthly P&L, cash and runway'!S5<=3),'Monthly P&L, cash and runway'!S5<=3,IF('Monthly P&L, cash and runway'!S5="","",'Monthly P&L, cash and runway'!S5<=3))),IF('Model inputs'!B52="","",'Model inputs'!B52),IF(IF(IF(ISERROR('Monthly P&L, cash and runway'!S5<=6),'Monthly P&L, cash and runway'!S5<=6,IF('Monthly P&L, cash and runway'!S5="","",'Monthly P&L, cash and runway'!S5<=6))="",FALSE,IF(ISERROR('Monthly P&L, cash and runway'!S5<=6),'Monthly P&L, cash and runway'!S5<=6,IF('Monthly P&L, cash and runway'!S5="","",'Monthly P&L, cash and runway'!S5<=6))),'Model inputs'!B52+('Model inputs'!B55-'Model inputs'!B52)*('Monthly P&L, cash and runway'!S5-3)/3,IF(IF(IF(ISERROR('Monthly P&L, cash and runway'!S5<=12),'Monthly P&L, cash and runway'!S5<=12,IF('Monthly P&L, cash and runway'!S5="","",'Monthly P&L, cash and runway'!S5<=12))="",FALSE,IF(ISERROR('Monthly P&L, cash and runway'!S5<=12),'Monthly P&L, cash and runway'!S5<=12,IF('Monthly P&L, cash and runway'!S5="","",'Monthly P&L, cash and runway'!S5<=12))),'Model inputs'!B55+('Model inputs'!B46-'Model inputs'!B55)*('Monthly P&L, cash and runway'!S5-6)/6,'Model inputs'!B46+('Model inputs'!B49-'Model inputs'!B46)*('Monthly P&L, cash and runway'!S5-12)/12))),0)) -> 28 | T7: =IF(IF(IF(ISERROR('Monthly P&L, cash and runway'!T5<1),'Monthly P&L, cash and runway'!T5<1,IF('Monthly P&L, cash and runway'!T5="","",'Monthly P&L, cash and runway'!T5<1))="",FALSE,IF(ISERROR('Monthly P&L, cash and runway'!T5<1),'Monthly P&L, cash and runway'!T5<1,IF('Monthly P&L, cash and runway'!T5="","",'Monthly P&L, cash and runway'!T5<1))),0,ROUND(IF(IF(IF(ISERROR('Monthly P&L, cash and runway'!T5<=3),'Monthly P&L, cash and runway'!T5<=3,IF('Monthly P&L, cash and runway'!T5="","",'Monthly P&L, cash and runway'!T5<=3))="",FALSE,IF(ISERROR('Monthly P&L, cash and runway'!T5<=3),'Monthly P&L, cash and runway'!T5<=3,IF('Monthly P&L, cash and runway'!T5="","",'Monthly P&L, cash and runway'!T5<=3))),IF('Model inputs'!B52="","",'Model inputs'!B52),IF(IF(IF(ISERROR('Monthly P&L, cash and runway'!T5<=6),'Monthly P&L, cash and runway'!T5<=6,IF('Monthly P&L, cash and runway'!T5="","",'Monthly P&L, cash and runway'!T5<=6))="",FALSE,IF(ISERROR('Monthly P&L, cash and runway'!T5<=6),'Monthly P&L, cash and runway'!T5<=6,IF('Monthly P&L, cash and runway'!T5="","",'Monthly P&L, cash and runway'!T5<=6))),'Model inputs'!B52+('Model inputs'!B55-'Model inputs'!B52)*('Monthly P&L, cash and runway'!T5-3)/3,IF(IF(IF(ISERROR('Monthly P&L, cash and runway'!T5<=12),'Monthly P&L, cash and runway'!T5<=12,IF('Monthly P&L, cash and runway'!T5="","",'Monthly P&L, cash and runway'!T5<=12))="",FALSE,IF(ISERROR('Monthly P&L, cash and runway'!T5<=12),'Monthly P&L, cash and runway'!T5<=12,IF('Monthly P&L, cash and runway'!T5="","",'Monthly P&L, cash and runway'!T5<=12))),'Model inputs'!B55+('Model inputs'!B46-'Model inputs'!B55)*('Monthly P&L, cash and runway'!T5-6)/6,'Model inputs'!B46+('Model inputs'!B49-'Model inputs'!B46)*('Monthly P&L, cash and runway'!T5-12)/12))),0)) -> 30 | U7: =IF(IF(IF(ISERROR('Monthly P&L, cash and runway'!U5<1),'Monthly P&L, cash and runway'!U5<1,IF('Monthly P&L, cash and runway'!U5="","",'Monthly P&L, cash and runway'!U5<1))="",FALSE,IF(ISERROR('Monthly P&L, cash and runway'!U5<1),'Monthly P&L, cash and runway'!U5<1,IF('Monthly P&L, cash and runway'!U5="","",'Monthly P&L, cash and runway'!U5<1))),0,ROUND(IF(IF(IF(ISERROR('Monthly P&L, cash and runway'!U5<=3),'Monthly P&L, cash and runway'!U5<=3,IF('Monthly P&L, cash and runway'!U5="","",'Monthly P&L, cash and runway'!U5<=3))="",FALSE,IF(ISERROR('Monthly P&L, cash and runway'!U5<=3),'Monthly P&L, cash and runway'!U5<=3,IF('Monthly P&L, cash and runway'!U5="","",'Monthly P&L, cash and runway'!U5<=3))),IF('Model inputs'!B52="","",'Model inputs'!B52),IF(IF(IF(ISERROR('Monthly P&L, cash and runway'!U5<=6),'Monthly P&L, cash and runway'!U5<=6,IF('Monthly P&L, cash and runway'!U5="","",'Monthly P&L, cash and runway'!U5<=6))="",FALSE,IF(ISERROR('Monthly P&L, cash and runway'!U5<=6),'Monthly P&L, cash and runway'!U5<=6,IF('Monthly P&L, cash and runway'!U5="","",'Monthly P&L, cash and runway'!U5<=6))),'Model inputs'!B52+('Model inputs'!B55-'Model inputs'!B52)*('Monthly P&L, cash and runway'!U5-3)/3,IF(IF(IF(ISERROR('Monthly P&L, cash and runway'!U5<=12),'Monthly P&L, cash and runway'!U5<=12,IF('Monthly P&L, cash and runway'!U5="","",'Monthly P&L, cash and runway'!U5<=12))="",FALSE,IF(ISERROR('Monthly P&L, cash and runway'!U5<=12),'Monthly P&L, cash and runway'!U5<=12,IF('Monthly P&L, cash and runway'!U5="","",'Monthly P&L, cash and runway'!U5<=12))),'Model inputs'!B55+('Model inputs'!B46-'Model inputs'!B55)*('Monthly P&L, cash and runway'!U5-6)/6,'Model inputs'!B46+('Model inputs'!B49-'Model inputs'!B46)*('Monthly P&L, cash and runway'!U5-12)/12))),0)) -> 32 | V7: =IF(IF(IF(ISERROR('Monthly P&L, cash and runway'!V5<1),'Monthly P&L, cash and runway'!V5<1,IF('Monthly P&L, cash and runway'!V5="","",'Monthly P&L, cash and runway'!V5<1))="",FALSE,IF(ISERROR('Monthly P&L, cash and runway'!V5<1),'Monthly P&L, cash and runway'!V5<1,IF('Monthly P&L, cash and runway'!V5="","",'Monthly P&L, cash and runway'!V5<1))),0,ROUND(IF(IF(IF(ISERROR('Monthly P&L, cash and runway'!V5<=3),'Monthly P&L, cash and runway'!V5<=3,IF('Monthly P&L, cash and runway'!V5="","",'Monthly P&L, cash and runway'!V5<=3))="",FALSE,IF(ISERROR('Monthly P&L, cash and runway'!V5<=3),'Monthly P&L, cash and runway'!V5<=3,IF('Monthly P&L, cash and runway'!V5="","",'Monthly P&L, cash and runway'!V5<=3))),IF('Model inputs'!B52="","",'Model inputs'!B52),IF(IF(IF(ISERROR('Monthly P&L, cash and runway'!V5<=6),'Monthly P&L, cash and runway'!V5<=6,IF('Monthly P&L, cash and runway'!V5="","",'Monthly P&L, cash and runway'!V5<=6))="",FALSE,IF(ISERROR('Monthly P&L, cash and runway'!V5<=6),'Monthly P&L, cash and runway'!V5<=6,IF('Monthly P&L, cash and runway'!V5="","",'Monthly P&L, cash and runway'!V5<=6))),'Model inputs'!B52+('Model inputs'!B55-'Model inputs'!B52)*('Monthly P&L, cash and runway'!V5-3)/3,IF(IF(IF(ISERROR('Monthly P&L, cash and runway'!V5<=12),'Monthly P&L, cash and runway'!V5<=12,IF('Monthly P&L, cash and runway'!V5="","",'Monthly P&L, cash and runway'!V5<=12))="",FALSE,IF(ISERROR('Monthly P&L, cash and runway'!V5<=12),'Monthly P&L, cash and runway'!V5<=12,IF('Monthly P&L, cash and runway'!V5="","",'Monthly P&L, cash and runway'!V5<=12))),'Model inputs'!B55+('Model inputs'!B46-'Model inputs'!B55)*('Monthly P&L, cash and runway'!V5-6)/6,'Model inputs'!B46+('Model inputs'!B49-'Model inputs'!B46)*('Monthly P&L, cash and runway'!V5-12)/12))),0)) -> 34 | W7: =IF(IF(IF(ISERROR('Monthly P&L, cash and runway'!W5<1),'Monthly P&L, cash and runway'!W5<1,IF('Monthly P&L, cash and runway'!W5="","",'Monthly P&L, cash and runway'!W5<1))="",FALSE,IF(ISERROR('Monthly P&L, cash and runway'!W5<1),'Monthly P&L, cash and runway'!W5<1,IF('Monthly P&L, cash and runway'!W5="","",'Monthly P&L, cash and runway'!W5<1))),0,ROUND(IF(IF(IF(ISERROR('Monthly P&L, cash and runway'!W5<=3),'Monthly P&L, cash and runway'!W5<=3,IF('Monthly P&L, cash and runway'!W5="","",'Monthly P&L, cash and runway'!W5<=3))="",FALSE,IF(ISERROR('Monthly P&L, cash and runway'!W5<=3),'Monthly P&L, cash and runway'!W5<=3,IF('Monthly P&L, cash and runway'!W5="","",'Monthly P&L, cash and runway'!W5<=3))),IF('Model inputs'!B52="","",'Model inputs'!B52),IF(IF(IF(ISERROR('Monthly P&L, cash and runway'!W5<=6),'Monthly P&L, cash and runway'!W5<=6,IF('Monthly P&L, cash and runway'!W5="","",'Monthly P&L, cash and runway'!W5<=6))="",FALSE,IF(ISERROR('Monthly P&L, cash and runway'!W5<=6),'Monthly P&L, cash and runway'!W5<=6,IF('Monthly P&L, cash and runway'!W5="","",'Monthly P&L, cash and runway'!W5<=6))),'Model inputs'!B52+('Model inputs'!B55-'Model inputs'!B52)*('Monthly P&L, cash and runway'!W5-3)/3,IF(IF(IF(ISERROR('Monthly P&L, cash and runway'!W5<=12),'Monthly P&L, cash and runway'!W5<=12,IF('Monthly P&L, cash and runway'!W5="","",'Monthly P&L, cash and runway'!W5<=12))="",FALSE,IF(ISERROR('Monthly P&L, cash and runway'!W5<=12),'Monthly P&L, cash and runway'!W5<=12,IF('Monthly P&L, cash and runway'!W5="","",'Monthly P&L, cash and runway'!W5<=12))),'Model inputs'!B55+('Model inputs'!B46-'Model inputs'!B55)*('Monthly P&L, cash and runway'!W5-6)/6,'Model inputs'!B46+('Model inputs'!B49-'Model inputs'!B46)*('Monthly P&L, cash and runway'!W5-12)/12))),0)) -> 36 | X7: =IF(IF(IF(ISERROR('Monthly P&L, cash and runway'!X5<1),'Monthly P&L, cash and runway'!X5<1,IF('Monthly P&L, cash and runway'!X5="","",'Monthly P&L, cash and runway'!X5<1))="",FALSE,IF(ISERROR('Monthly P&L, cash and runway'!X5<1),'Monthly P&L, cash and runway'!X5<1,IF('Monthly P&L, cash and runway'!X5="","",'Monthly P&L, cash and runway'!X5<1))),0,ROUND(IF(IF(IF(ISERROR('Monthly P&L, cash and runway'!X5<=3),'Monthly P&L, cash and runway'!X5<=3,IF('Monthly P&L, cash and runway'!X5="","",'Monthly P&L, cash and runway'!X5<=3))="",FALSE,IF(ISERROR('Monthly P&L, cash and runway'!X5<=3),'Monthly P&L, cash and runway'!X5<=3,IF('Monthly P&L, cash and runway'!X5="","",'Monthly P&L, cash and runway'!X5<=3))),IF('Model inputs'!B52="","",'Model inputs'!B52),IF(IF(IF(ISERROR('Monthly P&L, cash and runway'!X5<=6),'Monthly P&L, cash and runway'!X5<=6,IF('Monthly P&L, cash and runway'!X5="","",'Monthly P&L, cash and runway'!X5<=6))="",FALSE,IF(ISERROR('Monthly P&L, cash and runway'!X5<=6),'Monthly P&L, cash and runway'!X5<=6,IF('Monthly P&L, cash and runway'!X5="","",'Monthly P&L, cash and runway'!X5<=6))),'Model inputs'!B52+('Model inputs'!B55-'Model inputs'!B52)*('Monthly P&L, cash and runway'!X5-3)/3,IF(IF(IF(ISERROR('Monthly P&L, cash and runway'!X5<=12),'Monthly P&L, cash and runway'!X5<=12,IF('Monthly P&L, cash and runway'!X5="","",'Monthly P&L, cash and runway'!X5<=12))="",FALSE,IF(ISERROR('Monthly P&L, cash and runway'!X5<=12),'Monthly P&L, cash and runway'!X5<=12,IF('Monthly P&L, cash and runway'!X5="","",'Monthly P&L, cash and runway'!X5<=12))),'Model inputs'!B55+('Model inputs'!B46-'Model inputs'!B55)*('Monthly P&L, cash and runway'!X5-6)/6,'Model inputs'!B46+('Model inputs'!B49-'Model inputs'!B46)*('Monthly P&L, cash and runway'!X5-12)/12))),0)) -> 38 | Y7: =IF(IF(IF(ISERROR('Monthly P&L, cash and runway'!Y5<1),'Monthly P&L, cash and runway'!Y5<1,IF('Monthly P&L, cash and runway'!Y5="","",'Monthly P&L, cash and runway'!Y5<1))="",FALSE,IF(ISERROR('Monthly P&L, cash and runway'!Y5<1),'Monthly P&L, cash and runway'!Y5<1,IF('Monthly P&L, cash and runway'!Y5="","",'Monthly P&L, cash and runway'!Y5<1))),0,ROUND(IF(IF(IF(ISERROR('Monthly P&L, cash and runway'!Y5<=3),'Monthly P&L, cash and runway'!Y5<=3,IF('Monthly P&L, cash and runway'!Y5="","",'Monthly P&L, cash and runway'!Y5<=3))="",FALSE,IF(ISERROR('Monthly P&L, cash and runway'!Y5<=3),'Monthly P&L, cash and runway'!Y5<=3,IF('Monthly P&L, cash and runway'!Y5="","",'Monthly P&L, cash and runway'!Y5<=3))),IF('Model inputs'!B52="","",'Model inputs'!B52),IF(IF(IF(ISERROR('Monthly P&L, cash and runway'!Y5<=6),'Monthly P&L, cash and runway'!Y5<=6,IF('Monthly P&L, cash and runway'!Y5="","",'Monthly P&L, cash and runway'!Y5<=6))="",FALSE,IF(ISERROR('Monthly P&L, cash and runway'!Y5<=6),'Monthly P&L, cash and runway'!Y5<=6,IF('Monthly P&L, cash and runway'!Y5="","",'Monthly P&L, cash and runway'!Y5<=6))),'Model inputs'!B52+('Model inputs'!B55-'Model inputs'!B52)*('Monthly P&L, cash and runway'!Y5-3)/3,IF(IF(IF(ISERROR('Monthly P&L, cash and runway'!Y5<=12),'Monthly P&L, cash and runway'!Y5<=12,IF('Monthly P&L, cash and runway'!Y5="","",'Monthly P&L, cash and runway'!Y5<=12))="",FALSE,IF(ISERROR('Monthly P&L, cash and runway'!Y5<=12),'Monthly P&L, cash and runway'!Y5<=12,IF('Monthly P&L, cash and runway'!Y5="","",'Monthly P&L, cash and runway'!Y5<=12))),'Model inputs'!B55+('Model inputs'!B46-'Model inputs'!B55)*('Monthly P&L, cash and runway'!Y5-6)/6,'Model inputs'!B46+('Model inputs'!B49-'Model inputs'!B46)*('Monthly P&L, cash and runway'!Y5-12)/12))),0)) -> 40
